{
 "cells": [
  {
   "cell_type": "code",
   "execution_count": 15,
   "id": "b876f314",
   "metadata": {
    "scrolled": true
   },
   "outputs": [
    {
     "name": "stdout",
     "output_type": "stream",
     "text": [
      "2023-09-18 21:49:59,876 - kedro.extras.extensions.ipython - INFO - No path argument was provided. Using: /Users/gpalazzo/Desktop/dev/crypto_msc_thesis\n",
      "2023-09-18 21:50:00,128 - kedro.framework.session.store - INFO - `read()` not implemented for `BaseSessionStore`. Assuming empty store.\n",
      "2023-09-18 21:50:01,004 - kedro.extras.extensions.ipython - INFO - ** Kedro project crypto_thesis\n",
      "2023-09-18 21:50:01,006 - kedro.extras.extensions.ipython - INFO - Defined global variable `context`, `session`, `catalog` and `pipelines`\n",
      "2023-09-18 21:50:01,018 - kedro.extras.extensions.ipython - INFO - Registered line magic `run_viz`\n"
     ]
    }
   ],
   "source": [
    "%reload_kedro"
   ]
  },
  {
   "cell_type": "code",
   "execution_count": 16,
   "id": "81902b22",
   "metadata": {},
   "outputs": [],
   "source": [
    "from crypto_thesis.data_domains.modeling.lstm import _build_lstm_timestamps_seq\n",
    "from pprint import pprint\n",
    "from tensorflow.keras.wrappers.scikit_learn import KerasClassifier\n",
    "import tensorflow as tf\n",
    "import numpy as np\n",
    "from keras.engine.sequential import Sequential\n",
    "from keras.layers import LSTM, BatchNormalization, Dense, Dropout, Activation\n",
    "from keras.models import Sequential\n",
    "from keras.optimizers import Adam\n",
    "from keras.regularizers import l2\n",
    "from crypto_thesis.utils import optimize_params\n",
    "from sklearn.model_selection import GridSearchCV"
   ]
  },
  {
   "cell_type": "markdown",
   "id": "440db2ef",
   "metadata": {},
   "source": [
    "## Base"
   ]
  },
  {
   "cell_type": "code",
   "execution_count": 17,
   "id": "6ed6921d",
   "metadata": {},
   "outputs": [],
   "source": [
    "TARGET_COL = [\"label\"]\n",
    "INDEX_COL = \"window_nbr\""
   ]
  },
  {
   "cell_type": "code",
   "execution_count": 18,
   "id": "2ee0797c",
   "metadata": {},
   "outputs": [
    {
     "name": "stdout",
     "output_type": "stream",
     "text": [
      "2023-09-18 21:50:01,123 - kedro.io.data_catalog - INFO - Loading data from `master_table_train_multic` (ParquetDataSet)...\n",
      "2023-09-18 21:50:01,299 - kedro.io.data_catalog - INFO - Loading data from `params:lstm_timestamp_seq_length` (MemoryDataSet)...\n"
     ]
    }
   ],
   "source": [
    "mt_train_multic = catalog.load(\"master_table_train_multic\")\n",
    "seq_length = catalog.load(\"params:lstm_timestamp_seq_length\")"
   ]
  },
  {
   "cell_type": "markdown",
   "id": "02ddd60c",
   "metadata": {},
   "source": [
    "## LSTM"
   ]
  },
  {
   "cell_type": "code",
   "execution_count": 19,
   "id": "a8bbc25f",
   "metadata": {},
   "outputs": [],
   "source": [
    "# set numpy seed\n",
    "np.random.seed(0)\n",
    "# set tensorflow seed\n",
    "tf.random.set_seed(0)\n",
    "\n",
    "tf.keras.utils.disable_interactive_logging()"
   ]
  },
  {
   "cell_type": "code",
   "execution_count": 20,
   "id": "7f894191",
   "metadata": {},
   "outputs": [],
   "source": [
    "master_table_train = mt_train_multic.set_index(INDEX_COL)\n",
    "X_train, y_train = master_table_train.drop(columns=TARGET_COL), master_table_train[TARGET_COL]\n",
    "\n",
    "X_train_scaled_seq, y_train_scaled_seq = _build_lstm_timestamps_seq(X=X_train,\n",
    "                                                                    y=y_train,\n",
    "                                                                    seq_length=seq_length)"
   ]
  },
  {
   "cell_type": "code",
   "execution_count": 21,
   "id": "dfde0698",
   "metadata": {},
   "outputs": [
    {
     "name": "stdout",
     "output_type": "stream",
     "text": [
      "2023-09-18 21:50:01,795 - absl - INFO - Epoch 1/10\n",
      "2023-09-18 21:50:02,054 - absl - INFO - Epoch 1/10\n",
      "2023-09-18 21:50:02,353 - absl - INFO - Epoch 1/10\n",
      "2023-09-18 21:50:02,613 - absl - INFO - Epoch 1/10\n",
      "2023-09-18 21:50:02,873 - absl - INFO - Epoch 1/10\n",
      "2023-09-18 21:50:03,122 - absl - INFO - Epoch 1/10\n",
      "2023-09-18 21:50:03,391 - absl - INFO - Epoch 1/10\n",
      "2023-09-18 21:50:03,654 - absl - INFO - Epoch 1/10\n",
      "2023-09-18 21:50:03,917 - absl - INFO - Epoch 1/10\n",
      "2023-09-18 21:50:04,189 - absl - INFO - Epoch 1/10\n",
      "2023-09-18 21:50:04,442 - absl - INFO - Epoch 1/10\n",
      "2023-09-18 21:50:04,692 - absl - INFO - Epoch 1/10\n",
      "2023-09-18 21:50:04,940 - absl - INFO - Epoch 1/10\n",
      "2023-09-18 21:50:05,189 - absl - INFO - Epoch 1/10\n",
      "2023-09-18 21:50:05,810 - absl - INFO - Epoch 1/10\n",
      "2023-09-18 21:50:06,060 - absl - INFO - Epoch 1/10\n",
      "2023-09-18 21:50:06,320 - absl - INFO - Epoch 1/10\n",
      "2023-09-18 21:50:06,572 - absl - INFO - Epoch 1/10\n"
     ]
    },
    {
     "ename": "ValueError",
     "evalue": "\nAll the 18 fits failed.\nIt is very likely that your model is misconfigured.\nYou can try to debug the error by setting error_score='raise'.\n\nBelow are more details about the failures:\n--------------------------------------------------------------------------------\n1 fits failed with the following error:\nTraceback (most recent call last):\n  File \"/Users/gpalazzo/anaconda3/envs/msc/lib/python3.8/site-packages/sklearn/model_selection/_validation.py\", line 686, in _fit_and_score\n    estimator.fit(X_train, y_train, **fit_params)\n  File \"/Users/gpalazzo/anaconda3/envs/msc/lib/python3.8/site-packages/keras/wrappers/scikit_learn.py\", line 248, in fit\n    return super().fit(x, y, **kwargs)\n  File \"/Users/gpalazzo/anaconda3/envs/msc/lib/python3.8/site-packages/keras/wrappers/scikit_learn.py\", line 175, in fit\n    history = self.model.fit(x, y, **fit_args)\n  File \"/Users/gpalazzo/anaconda3/envs/msc/lib/python3.8/site-packages/keras/utils/traceback_utils.py\", line 70, in error_handler\n    raise e.with_traceback(filtered_tb) from None\n  File \"/var/folders/dv/bgkf3r6s72j37pb4gm7dxtrr0000gn/T/__autograph_generated_filembb5nbmh.py\", line 15, in tf__train_function\n    retval_ = ag__.converted_call(ag__.ld(step_function), (ag__.ld(self), ag__.ld(iterator)), None, fscope)\nValueError: in user code:\n\n    File \"/Users/gpalazzo/anaconda3/envs/msc/lib/python3.8/site-packages/keras/engine/training.py\", line 1284, in train_function  *\n        return step_function(self, iterator)\n    File \"/Users/gpalazzo/anaconda3/envs/msc/lib/python3.8/site-packages/keras/engine/training.py\", line 1268, in step_function  **\n        outputs = model.distribute_strategy.run(run_step, args=(data,))\n    File \"/Users/gpalazzo/anaconda3/envs/msc/lib/python3.8/site-packages/keras/engine/training.py\", line 1249, in run_step  **\n        outputs = model.train_step(data)\n    File \"/Users/gpalazzo/anaconda3/envs/msc/lib/python3.8/site-packages/keras/engine/training.py\", line 1050, in train_step\n        y_pred = self(x, training=True)\n    File \"/Users/gpalazzo/anaconda3/envs/msc/lib/python3.8/site-packages/keras/utils/traceback_utils.py\", line 70, in error_handler\n        raise e.with_traceback(filtered_tb) from None\n    File \"/Users/gpalazzo/anaconda3/envs/msc/lib/python3.8/site-packages/keras/engine/input_spec.py\", line 298, in assert_input_compatibility\n        raise ValueError(\n\n    ValueError: Input 0 of layer \"sequential_18\" is incompatible with the layer: expected shape=(None, 1, 30), found shape=(4, 30)\n\n\n--------------------------------------------------------------------------------\n1 fits failed with the following error:\nTraceback (most recent call last):\n  File \"/Users/gpalazzo/anaconda3/envs/msc/lib/python3.8/site-packages/sklearn/model_selection/_validation.py\", line 686, in _fit_and_score\n    estimator.fit(X_train, y_train, **fit_params)\n  File \"/Users/gpalazzo/anaconda3/envs/msc/lib/python3.8/site-packages/keras/wrappers/scikit_learn.py\", line 248, in fit\n    return super().fit(x, y, **kwargs)\n  File \"/Users/gpalazzo/anaconda3/envs/msc/lib/python3.8/site-packages/keras/wrappers/scikit_learn.py\", line 175, in fit\n    history = self.model.fit(x, y, **fit_args)\n  File \"/Users/gpalazzo/anaconda3/envs/msc/lib/python3.8/site-packages/keras/utils/traceback_utils.py\", line 70, in error_handler\n    raise e.with_traceback(filtered_tb) from None\n  File \"/var/folders/dv/bgkf3r6s72j37pb4gm7dxtrr0000gn/T/__autograph_generated_filembb5nbmh.py\", line 15, in tf__train_function\n    retval_ = ag__.converted_call(ag__.ld(step_function), (ag__.ld(self), ag__.ld(iterator)), None, fscope)\nValueError: in user code:\n\n    File \"/Users/gpalazzo/anaconda3/envs/msc/lib/python3.8/site-packages/keras/engine/training.py\", line 1284, in train_function  *\n        return step_function(self, iterator)\n    File \"/Users/gpalazzo/anaconda3/envs/msc/lib/python3.8/site-packages/keras/engine/training.py\", line 1268, in step_function  **\n        outputs = model.distribute_strategy.run(run_step, args=(data,))\n    File \"/Users/gpalazzo/anaconda3/envs/msc/lib/python3.8/site-packages/keras/engine/training.py\", line 1249, in run_step  **\n        outputs = model.train_step(data)\n    File \"/Users/gpalazzo/anaconda3/envs/msc/lib/python3.8/site-packages/keras/engine/training.py\", line 1050, in train_step\n        y_pred = self(x, training=True)\n    File \"/Users/gpalazzo/anaconda3/envs/msc/lib/python3.8/site-packages/keras/utils/traceback_utils.py\", line 70, in error_handler\n        raise e.with_traceback(filtered_tb) from None\n    File \"/Users/gpalazzo/anaconda3/envs/msc/lib/python3.8/site-packages/keras/engine/input_spec.py\", line 298, in assert_input_compatibility\n        raise ValueError(\n\n    ValueError: Input 0 of layer \"sequential_19\" is incompatible with the layer: expected shape=(None, 1, 30), found shape=(4, 30)\n\n\n--------------------------------------------------------------------------------\n1 fits failed with the following error:\nTraceback (most recent call last):\n  File \"/Users/gpalazzo/anaconda3/envs/msc/lib/python3.8/site-packages/sklearn/model_selection/_validation.py\", line 686, in _fit_and_score\n    estimator.fit(X_train, y_train, **fit_params)\n  File \"/Users/gpalazzo/anaconda3/envs/msc/lib/python3.8/site-packages/keras/wrappers/scikit_learn.py\", line 248, in fit\n    return super().fit(x, y, **kwargs)\n  File \"/Users/gpalazzo/anaconda3/envs/msc/lib/python3.8/site-packages/keras/wrappers/scikit_learn.py\", line 175, in fit\n    history = self.model.fit(x, y, **fit_args)\n  File \"/Users/gpalazzo/anaconda3/envs/msc/lib/python3.8/site-packages/keras/utils/traceback_utils.py\", line 70, in error_handler\n    raise e.with_traceback(filtered_tb) from None\n  File \"/var/folders/dv/bgkf3r6s72j37pb4gm7dxtrr0000gn/T/__autograph_generated_filembb5nbmh.py\", line 15, in tf__train_function\n    retval_ = ag__.converted_call(ag__.ld(step_function), (ag__.ld(self), ag__.ld(iterator)), None, fscope)\nValueError: in user code:\n\n    File \"/Users/gpalazzo/anaconda3/envs/msc/lib/python3.8/site-packages/keras/engine/training.py\", line 1284, in train_function  *\n        return step_function(self, iterator)\n    File \"/Users/gpalazzo/anaconda3/envs/msc/lib/python3.8/site-packages/keras/engine/training.py\", line 1268, in step_function  **\n        outputs = model.distribute_strategy.run(run_step, args=(data,))\n    File \"/Users/gpalazzo/anaconda3/envs/msc/lib/python3.8/site-packages/keras/engine/training.py\", line 1249, in run_step  **\n        outputs = model.train_step(data)\n    File \"/Users/gpalazzo/anaconda3/envs/msc/lib/python3.8/site-packages/keras/engine/training.py\", line 1050, in train_step\n        y_pred = self(x, training=True)\n    File \"/Users/gpalazzo/anaconda3/envs/msc/lib/python3.8/site-packages/keras/utils/traceback_utils.py\", line 70, in error_handler\n        raise e.with_traceback(filtered_tb) from None\n    File \"/Users/gpalazzo/anaconda3/envs/msc/lib/python3.8/site-packages/keras/engine/input_spec.py\", line 298, in assert_input_compatibility\n        raise ValueError(\n\n    ValueError: Input 0 of layer \"sequential_20\" is incompatible with the layer: expected shape=(None, 1, 30), found shape=(4, 30)\n\n\n--------------------------------------------------------------------------------\n1 fits failed with the following error:\nTraceback (most recent call last):\n  File \"/Users/gpalazzo/anaconda3/envs/msc/lib/python3.8/site-packages/sklearn/model_selection/_validation.py\", line 686, in _fit_and_score\n    estimator.fit(X_train, y_train, **fit_params)\n  File \"/Users/gpalazzo/anaconda3/envs/msc/lib/python3.8/site-packages/keras/wrappers/scikit_learn.py\", line 248, in fit\n    return super().fit(x, y, **kwargs)\n  File \"/Users/gpalazzo/anaconda3/envs/msc/lib/python3.8/site-packages/keras/wrappers/scikit_learn.py\", line 175, in fit\n    history = self.model.fit(x, y, **fit_args)\n  File \"/Users/gpalazzo/anaconda3/envs/msc/lib/python3.8/site-packages/keras/utils/traceback_utils.py\", line 70, in error_handler\n    raise e.with_traceback(filtered_tb) from None\n  File \"/var/folders/dv/bgkf3r6s72j37pb4gm7dxtrr0000gn/T/__autograph_generated_filembb5nbmh.py\", line 15, in tf__train_function\n    retval_ = ag__.converted_call(ag__.ld(step_function), (ag__.ld(self), ag__.ld(iterator)), None, fscope)\nValueError: in user code:\n\n    File \"/Users/gpalazzo/anaconda3/envs/msc/lib/python3.8/site-packages/keras/engine/training.py\", line 1284, in train_function  *\n        return step_function(self, iterator)\n    File \"/Users/gpalazzo/anaconda3/envs/msc/lib/python3.8/site-packages/keras/engine/training.py\", line 1268, in step_function  **\n        outputs = model.distribute_strategy.run(run_step, args=(data,))\n    File \"/Users/gpalazzo/anaconda3/envs/msc/lib/python3.8/site-packages/keras/engine/training.py\", line 1249, in run_step  **\n        outputs = model.train_step(data)\n    File \"/Users/gpalazzo/anaconda3/envs/msc/lib/python3.8/site-packages/keras/engine/training.py\", line 1050, in train_step\n        y_pred = self(x, training=True)\n    File \"/Users/gpalazzo/anaconda3/envs/msc/lib/python3.8/site-packages/keras/utils/traceback_utils.py\", line 70, in error_handler\n        raise e.with_traceback(filtered_tb) from None\n    File \"/Users/gpalazzo/anaconda3/envs/msc/lib/python3.8/site-packages/keras/engine/input_spec.py\", line 298, in assert_input_compatibility\n        raise ValueError(\n\n    ValueError: Input 0 of layer \"sequential_21\" is incompatible with the layer: expected shape=(None, 1, 30), found shape=(4, 30)\n\n\n--------------------------------------------------------------------------------\n1 fits failed with the following error:\nTraceback (most recent call last):\n  File \"/Users/gpalazzo/anaconda3/envs/msc/lib/python3.8/site-packages/sklearn/model_selection/_validation.py\", line 686, in _fit_and_score\n    estimator.fit(X_train, y_train, **fit_params)\n  File \"/Users/gpalazzo/anaconda3/envs/msc/lib/python3.8/site-packages/keras/wrappers/scikit_learn.py\", line 248, in fit\n    return super().fit(x, y, **kwargs)\n  File \"/Users/gpalazzo/anaconda3/envs/msc/lib/python3.8/site-packages/keras/wrappers/scikit_learn.py\", line 175, in fit\n    history = self.model.fit(x, y, **fit_args)\n  File \"/Users/gpalazzo/anaconda3/envs/msc/lib/python3.8/site-packages/keras/utils/traceback_utils.py\", line 70, in error_handler\n    raise e.with_traceback(filtered_tb) from None\n  File \"/var/folders/dv/bgkf3r6s72j37pb4gm7dxtrr0000gn/T/__autograph_generated_filembb5nbmh.py\", line 15, in tf__train_function\n    retval_ = ag__.converted_call(ag__.ld(step_function), (ag__.ld(self), ag__.ld(iterator)), None, fscope)\nValueError: in user code:\n\n    File \"/Users/gpalazzo/anaconda3/envs/msc/lib/python3.8/site-packages/keras/engine/training.py\", line 1284, in train_function  *\n        return step_function(self, iterator)\n    File \"/Users/gpalazzo/anaconda3/envs/msc/lib/python3.8/site-packages/keras/engine/training.py\", line 1268, in step_function  **\n        outputs = model.distribute_strategy.run(run_step, args=(data,))\n    File \"/Users/gpalazzo/anaconda3/envs/msc/lib/python3.8/site-packages/keras/engine/training.py\", line 1249, in run_step  **\n        outputs = model.train_step(data)\n    File \"/Users/gpalazzo/anaconda3/envs/msc/lib/python3.8/site-packages/keras/engine/training.py\", line 1050, in train_step\n        y_pred = self(x, training=True)\n    File \"/Users/gpalazzo/anaconda3/envs/msc/lib/python3.8/site-packages/keras/utils/traceback_utils.py\", line 70, in error_handler\n        raise e.with_traceback(filtered_tb) from None\n    File \"/Users/gpalazzo/anaconda3/envs/msc/lib/python3.8/site-packages/keras/engine/input_spec.py\", line 298, in assert_input_compatibility\n        raise ValueError(\n\n    ValueError: Input 0 of layer \"sequential_22\" is incompatible with the layer: expected shape=(None, 1, 30), found shape=(4, 30)\n\n\n--------------------------------------------------------------------------------\n1 fits failed with the following error:\nTraceback (most recent call last):\n  File \"/Users/gpalazzo/anaconda3/envs/msc/lib/python3.8/site-packages/sklearn/model_selection/_validation.py\", line 686, in _fit_and_score\n    estimator.fit(X_train, y_train, **fit_params)\n  File \"/Users/gpalazzo/anaconda3/envs/msc/lib/python3.8/site-packages/keras/wrappers/scikit_learn.py\", line 248, in fit\n    return super().fit(x, y, **kwargs)\n  File \"/Users/gpalazzo/anaconda3/envs/msc/lib/python3.8/site-packages/keras/wrappers/scikit_learn.py\", line 175, in fit\n    history = self.model.fit(x, y, **fit_args)\n  File \"/Users/gpalazzo/anaconda3/envs/msc/lib/python3.8/site-packages/keras/utils/traceback_utils.py\", line 70, in error_handler\n    raise e.with_traceback(filtered_tb) from None\n  File \"/var/folders/dv/bgkf3r6s72j37pb4gm7dxtrr0000gn/T/__autograph_generated_filembb5nbmh.py\", line 15, in tf__train_function\n    retval_ = ag__.converted_call(ag__.ld(step_function), (ag__.ld(self), ag__.ld(iterator)), None, fscope)\nValueError: in user code:\n\n    File \"/Users/gpalazzo/anaconda3/envs/msc/lib/python3.8/site-packages/keras/engine/training.py\", line 1284, in train_function  *\n        return step_function(self, iterator)\n    File \"/Users/gpalazzo/anaconda3/envs/msc/lib/python3.8/site-packages/keras/engine/training.py\", line 1268, in step_function  **\n        outputs = model.distribute_strategy.run(run_step, args=(data,))\n    File \"/Users/gpalazzo/anaconda3/envs/msc/lib/python3.8/site-packages/keras/engine/training.py\", line 1249, in run_step  **\n        outputs = model.train_step(data)\n    File \"/Users/gpalazzo/anaconda3/envs/msc/lib/python3.8/site-packages/keras/engine/training.py\", line 1050, in train_step\n        y_pred = self(x, training=True)\n    File \"/Users/gpalazzo/anaconda3/envs/msc/lib/python3.8/site-packages/keras/utils/traceback_utils.py\", line 70, in error_handler\n        raise e.with_traceback(filtered_tb) from None\n    File \"/Users/gpalazzo/anaconda3/envs/msc/lib/python3.8/site-packages/keras/engine/input_spec.py\", line 298, in assert_input_compatibility\n        raise ValueError(\n\n    ValueError: Input 0 of layer \"sequential_23\" is incompatible with the layer: expected shape=(None, 1, 30), found shape=(4, 30)\n\n\n--------------------------------------------------------------------------------\n1 fits failed with the following error:\nTraceback (most recent call last):\n  File \"/Users/gpalazzo/anaconda3/envs/msc/lib/python3.8/site-packages/sklearn/model_selection/_validation.py\", line 686, in _fit_and_score\n    estimator.fit(X_train, y_train, **fit_params)\n  File \"/Users/gpalazzo/anaconda3/envs/msc/lib/python3.8/site-packages/keras/wrappers/scikit_learn.py\", line 248, in fit\n    return super().fit(x, y, **kwargs)\n  File \"/Users/gpalazzo/anaconda3/envs/msc/lib/python3.8/site-packages/keras/wrappers/scikit_learn.py\", line 175, in fit\n    history = self.model.fit(x, y, **fit_args)\n  File \"/Users/gpalazzo/anaconda3/envs/msc/lib/python3.8/site-packages/keras/utils/traceback_utils.py\", line 70, in error_handler\n    raise e.with_traceback(filtered_tb) from None\n  File \"/var/folders/dv/bgkf3r6s72j37pb4gm7dxtrr0000gn/T/__autograph_generated_filembb5nbmh.py\", line 15, in tf__train_function\n    retval_ = ag__.converted_call(ag__.ld(step_function), (ag__.ld(self), ag__.ld(iterator)), None, fscope)\nValueError: in user code:\n\n    File \"/Users/gpalazzo/anaconda3/envs/msc/lib/python3.8/site-packages/keras/engine/training.py\", line 1284, in train_function  *\n        return step_function(self, iterator)\n    File \"/Users/gpalazzo/anaconda3/envs/msc/lib/python3.8/site-packages/keras/engine/training.py\", line 1268, in step_function  **\n        outputs = model.distribute_strategy.run(run_step, args=(data,))\n    File \"/Users/gpalazzo/anaconda3/envs/msc/lib/python3.8/site-packages/keras/engine/training.py\", line 1249, in run_step  **\n        outputs = model.train_step(data)\n    File \"/Users/gpalazzo/anaconda3/envs/msc/lib/python3.8/site-packages/keras/engine/training.py\", line 1050, in train_step\n        y_pred = self(x, training=True)\n    File \"/Users/gpalazzo/anaconda3/envs/msc/lib/python3.8/site-packages/keras/utils/traceback_utils.py\", line 70, in error_handler\n        raise e.with_traceback(filtered_tb) from None\n    File \"/Users/gpalazzo/anaconda3/envs/msc/lib/python3.8/site-packages/keras/engine/input_spec.py\", line 298, in assert_input_compatibility\n        raise ValueError(\n\n    ValueError: Input 0 of layer \"sequential_24\" is incompatible with the layer: expected shape=(None, 1, 30), found shape=(4, 30)\n\n\n--------------------------------------------------------------------------------\n1 fits failed with the following error:\nTraceback (most recent call last):\n  File \"/Users/gpalazzo/anaconda3/envs/msc/lib/python3.8/site-packages/sklearn/model_selection/_validation.py\", line 686, in _fit_and_score\n    estimator.fit(X_train, y_train, **fit_params)\n  File \"/Users/gpalazzo/anaconda3/envs/msc/lib/python3.8/site-packages/keras/wrappers/scikit_learn.py\", line 248, in fit\n    return super().fit(x, y, **kwargs)\n  File \"/Users/gpalazzo/anaconda3/envs/msc/lib/python3.8/site-packages/keras/wrappers/scikit_learn.py\", line 175, in fit\n    history = self.model.fit(x, y, **fit_args)\n  File \"/Users/gpalazzo/anaconda3/envs/msc/lib/python3.8/site-packages/keras/utils/traceback_utils.py\", line 70, in error_handler\n    raise e.with_traceback(filtered_tb) from None\n  File \"/var/folders/dv/bgkf3r6s72j37pb4gm7dxtrr0000gn/T/__autograph_generated_filembb5nbmh.py\", line 15, in tf__train_function\n    retval_ = ag__.converted_call(ag__.ld(step_function), (ag__.ld(self), ag__.ld(iterator)), None, fscope)\nValueError: in user code:\n\n    File \"/Users/gpalazzo/anaconda3/envs/msc/lib/python3.8/site-packages/keras/engine/training.py\", line 1284, in train_function  *\n        return step_function(self, iterator)\n    File \"/Users/gpalazzo/anaconda3/envs/msc/lib/python3.8/site-packages/keras/engine/training.py\", line 1268, in step_function  **\n        outputs = model.distribute_strategy.run(run_step, args=(data,))\n    File \"/Users/gpalazzo/anaconda3/envs/msc/lib/python3.8/site-packages/keras/engine/training.py\", line 1249, in run_step  **\n        outputs = model.train_step(data)\n    File \"/Users/gpalazzo/anaconda3/envs/msc/lib/python3.8/site-packages/keras/engine/training.py\", line 1050, in train_step\n        y_pred = self(x, training=True)\n    File \"/Users/gpalazzo/anaconda3/envs/msc/lib/python3.8/site-packages/keras/utils/traceback_utils.py\", line 70, in error_handler\n        raise e.with_traceback(filtered_tb) from None\n    File \"/Users/gpalazzo/anaconda3/envs/msc/lib/python3.8/site-packages/keras/engine/input_spec.py\", line 298, in assert_input_compatibility\n        raise ValueError(\n\n    ValueError: Input 0 of layer \"sequential_25\" is incompatible with the layer: expected shape=(None, 1, 30), found shape=(4, 30)\n\n\n--------------------------------------------------------------------------------\n1 fits failed with the following error:\nTraceback (most recent call last):\n  File \"/Users/gpalazzo/anaconda3/envs/msc/lib/python3.8/site-packages/sklearn/model_selection/_validation.py\", line 686, in _fit_and_score\n    estimator.fit(X_train, y_train, **fit_params)\n  File \"/Users/gpalazzo/anaconda3/envs/msc/lib/python3.8/site-packages/keras/wrappers/scikit_learn.py\", line 248, in fit\n    return super().fit(x, y, **kwargs)\n  File \"/Users/gpalazzo/anaconda3/envs/msc/lib/python3.8/site-packages/keras/wrappers/scikit_learn.py\", line 175, in fit\n    history = self.model.fit(x, y, **fit_args)\n  File \"/Users/gpalazzo/anaconda3/envs/msc/lib/python3.8/site-packages/keras/utils/traceback_utils.py\", line 70, in error_handler\n    raise e.with_traceback(filtered_tb) from None\n  File \"/var/folders/dv/bgkf3r6s72j37pb4gm7dxtrr0000gn/T/__autograph_generated_filembb5nbmh.py\", line 15, in tf__train_function\n    retval_ = ag__.converted_call(ag__.ld(step_function), (ag__.ld(self), ag__.ld(iterator)), None, fscope)\nValueError: in user code:\n\n    File \"/Users/gpalazzo/anaconda3/envs/msc/lib/python3.8/site-packages/keras/engine/training.py\", line 1284, in train_function  *\n        return step_function(self, iterator)\n    File \"/Users/gpalazzo/anaconda3/envs/msc/lib/python3.8/site-packages/keras/engine/training.py\", line 1268, in step_function  **\n        outputs = model.distribute_strategy.run(run_step, args=(data,))\n    File \"/Users/gpalazzo/anaconda3/envs/msc/lib/python3.8/site-packages/keras/engine/training.py\", line 1249, in run_step  **\n        outputs = model.train_step(data)\n    File \"/Users/gpalazzo/anaconda3/envs/msc/lib/python3.8/site-packages/keras/engine/training.py\", line 1050, in train_step\n        y_pred = self(x, training=True)\n    File \"/Users/gpalazzo/anaconda3/envs/msc/lib/python3.8/site-packages/keras/utils/traceback_utils.py\", line 70, in error_handler\n        raise e.with_traceback(filtered_tb) from None\n    File \"/Users/gpalazzo/anaconda3/envs/msc/lib/python3.8/site-packages/keras/engine/input_spec.py\", line 298, in assert_input_compatibility\n        raise ValueError(\n\n    ValueError: Input 0 of layer \"sequential_26\" is incompatible with the layer: expected shape=(None, 1, 30), found shape=(4, 30)\n\n\n--------------------------------------------------------------------------------\n1 fits failed with the following error:\nTraceback (most recent call last):\n  File \"/Users/gpalazzo/anaconda3/envs/msc/lib/python3.8/site-packages/sklearn/model_selection/_validation.py\", line 686, in _fit_and_score\n    estimator.fit(X_train, y_train, **fit_params)\n  File \"/Users/gpalazzo/anaconda3/envs/msc/lib/python3.8/site-packages/keras/wrappers/scikit_learn.py\", line 248, in fit\n    return super().fit(x, y, **kwargs)\n  File \"/Users/gpalazzo/anaconda3/envs/msc/lib/python3.8/site-packages/keras/wrappers/scikit_learn.py\", line 175, in fit\n    history = self.model.fit(x, y, **fit_args)\n  File \"/Users/gpalazzo/anaconda3/envs/msc/lib/python3.8/site-packages/keras/utils/traceback_utils.py\", line 70, in error_handler\n    raise e.with_traceback(filtered_tb) from None\n  File \"/var/folders/dv/bgkf3r6s72j37pb4gm7dxtrr0000gn/T/__autograph_generated_filembb5nbmh.py\", line 15, in tf__train_function\n    retval_ = ag__.converted_call(ag__.ld(step_function), (ag__.ld(self), ag__.ld(iterator)), None, fscope)\nValueError: in user code:\n\n    File \"/Users/gpalazzo/anaconda3/envs/msc/lib/python3.8/site-packages/keras/engine/training.py\", line 1284, in train_function  *\n        return step_function(self, iterator)\n    File \"/Users/gpalazzo/anaconda3/envs/msc/lib/python3.8/site-packages/keras/engine/training.py\", line 1268, in step_function  **\n        outputs = model.distribute_strategy.run(run_step, args=(data,))\n    File \"/Users/gpalazzo/anaconda3/envs/msc/lib/python3.8/site-packages/keras/engine/training.py\", line 1249, in run_step  **\n        outputs = model.train_step(data)\n    File \"/Users/gpalazzo/anaconda3/envs/msc/lib/python3.8/site-packages/keras/engine/training.py\", line 1050, in train_step\n        y_pred = self(x, training=True)\n    File \"/Users/gpalazzo/anaconda3/envs/msc/lib/python3.8/site-packages/keras/utils/traceback_utils.py\", line 70, in error_handler\n        raise e.with_traceback(filtered_tb) from None\n    File \"/Users/gpalazzo/anaconda3/envs/msc/lib/python3.8/site-packages/keras/engine/input_spec.py\", line 298, in assert_input_compatibility\n        raise ValueError(\n\n    ValueError: Input 0 of layer \"sequential_27\" is incompatible with the layer: expected shape=(None, 1, 30), found shape=(16, 30)\n\n\n--------------------------------------------------------------------------------\n1 fits failed with the following error:\nTraceback (most recent call last):\n  File \"/Users/gpalazzo/anaconda3/envs/msc/lib/python3.8/site-packages/sklearn/model_selection/_validation.py\", line 686, in _fit_and_score\n    estimator.fit(X_train, y_train, **fit_params)\n  File \"/Users/gpalazzo/anaconda3/envs/msc/lib/python3.8/site-packages/keras/wrappers/scikit_learn.py\", line 248, in fit\n    return super().fit(x, y, **kwargs)\n  File \"/Users/gpalazzo/anaconda3/envs/msc/lib/python3.8/site-packages/keras/wrappers/scikit_learn.py\", line 175, in fit\n    history = self.model.fit(x, y, **fit_args)\n  File \"/Users/gpalazzo/anaconda3/envs/msc/lib/python3.8/site-packages/keras/utils/traceback_utils.py\", line 70, in error_handler\n    raise e.with_traceback(filtered_tb) from None\n  File \"/var/folders/dv/bgkf3r6s72j37pb4gm7dxtrr0000gn/T/__autograph_generated_filembb5nbmh.py\", line 15, in tf__train_function\n    retval_ = ag__.converted_call(ag__.ld(step_function), (ag__.ld(self), ag__.ld(iterator)), None, fscope)\nValueError: in user code:\n\n    File \"/Users/gpalazzo/anaconda3/envs/msc/lib/python3.8/site-packages/keras/engine/training.py\", line 1284, in train_function  *\n        return step_function(self, iterator)\n    File \"/Users/gpalazzo/anaconda3/envs/msc/lib/python3.8/site-packages/keras/engine/training.py\", line 1268, in step_function  **\n        outputs = model.distribute_strategy.run(run_step, args=(data,))\n    File \"/Users/gpalazzo/anaconda3/envs/msc/lib/python3.8/site-packages/keras/engine/training.py\", line 1249, in run_step  **\n        outputs = model.train_step(data)\n    File \"/Users/gpalazzo/anaconda3/envs/msc/lib/python3.8/site-packages/keras/engine/training.py\", line 1050, in train_step\n        y_pred = self(x, training=True)\n    File \"/Users/gpalazzo/anaconda3/envs/msc/lib/python3.8/site-packages/keras/utils/traceback_utils.py\", line 70, in error_handler\n        raise e.with_traceback(filtered_tb) from None\n    File \"/Users/gpalazzo/anaconda3/envs/msc/lib/python3.8/site-packages/keras/engine/input_spec.py\", line 298, in assert_input_compatibility\n        raise ValueError(\n\n    ValueError: Input 0 of layer \"sequential_28\" is incompatible with the layer: expected shape=(None, 1, 30), found shape=(16, 30)\n\n\n--------------------------------------------------------------------------------\n1 fits failed with the following error:\nTraceback (most recent call last):\n  File \"/Users/gpalazzo/anaconda3/envs/msc/lib/python3.8/site-packages/sklearn/model_selection/_validation.py\", line 686, in _fit_and_score\n    estimator.fit(X_train, y_train, **fit_params)\n  File \"/Users/gpalazzo/anaconda3/envs/msc/lib/python3.8/site-packages/keras/wrappers/scikit_learn.py\", line 248, in fit\n    return super().fit(x, y, **kwargs)\n  File \"/Users/gpalazzo/anaconda3/envs/msc/lib/python3.8/site-packages/keras/wrappers/scikit_learn.py\", line 175, in fit\n    history = self.model.fit(x, y, **fit_args)\n  File \"/Users/gpalazzo/anaconda3/envs/msc/lib/python3.8/site-packages/keras/utils/traceback_utils.py\", line 70, in error_handler\n    raise e.with_traceback(filtered_tb) from None\n  File \"/var/folders/dv/bgkf3r6s72j37pb4gm7dxtrr0000gn/T/__autograph_generated_filembb5nbmh.py\", line 15, in tf__train_function\n    retval_ = ag__.converted_call(ag__.ld(step_function), (ag__.ld(self), ag__.ld(iterator)), None, fscope)\nValueError: in user code:\n\n    File \"/Users/gpalazzo/anaconda3/envs/msc/lib/python3.8/site-packages/keras/engine/training.py\", line 1284, in train_function  *\n        return step_function(self, iterator)\n    File \"/Users/gpalazzo/anaconda3/envs/msc/lib/python3.8/site-packages/keras/engine/training.py\", line 1268, in step_function  **\n        outputs = model.distribute_strategy.run(run_step, args=(data,))\n    File \"/Users/gpalazzo/anaconda3/envs/msc/lib/python3.8/site-packages/keras/engine/training.py\", line 1249, in run_step  **\n        outputs = model.train_step(data)\n    File \"/Users/gpalazzo/anaconda3/envs/msc/lib/python3.8/site-packages/keras/engine/training.py\", line 1050, in train_step\n        y_pred = self(x, training=True)\n    File \"/Users/gpalazzo/anaconda3/envs/msc/lib/python3.8/site-packages/keras/utils/traceback_utils.py\", line 70, in error_handler\n        raise e.with_traceback(filtered_tb) from None\n    File \"/Users/gpalazzo/anaconda3/envs/msc/lib/python3.8/site-packages/keras/engine/input_spec.py\", line 298, in assert_input_compatibility\n        raise ValueError(\n\n    ValueError: Input 0 of layer \"sequential_29\" is incompatible with the layer: expected shape=(None, 1, 30), found shape=(16, 30)\n\n\n--------------------------------------------------------------------------------\n1 fits failed with the following error:\nTraceback (most recent call last):\n  File \"/Users/gpalazzo/anaconda3/envs/msc/lib/python3.8/site-packages/sklearn/model_selection/_validation.py\", line 686, in _fit_and_score\n    estimator.fit(X_train, y_train, **fit_params)\n  File \"/Users/gpalazzo/anaconda3/envs/msc/lib/python3.8/site-packages/keras/wrappers/scikit_learn.py\", line 248, in fit\n    return super().fit(x, y, **kwargs)\n  File \"/Users/gpalazzo/anaconda3/envs/msc/lib/python3.8/site-packages/keras/wrappers/scikit_learn.py\", line 175, in fit\n    history = self.model.fit(x, y, **fit_args)\n  File \"/Users/gpalazzo/anaconda3/envs/msc/lib/python3.8/site-packages/keras/utils/traceback_utils.py\", line 70, in error_handler\n    raise e.with_traceback(filtered_tb) from None\n  File \"/var/folders/dv/bgkf3r6s72j37pb4gm7dxtrr0000gn/T/__autograph_generated_filembb5nbmh.py\", line 15, in tf__train_function\n    retval_ = ag__.converted_call(ag__.ld(step_function), (ag__.ld(self), ag__.ld(iterator)), None, fscope)\nValueError: in user code:\n\n    File \"/Users/gpalazzo/anaconda3/envs/msc/lib/python3.8/site-packages/keras/engine/training.py\", line 1284, in train_function  *\n        return step_function(self, iterator)\n    File \"/Users/gpalazzo/anaconda3/envs/msc/lib/python3.8/site-packages/keras/engine/training.py\", line 1268, in step_function  **\n        outputs = model.distribute_strategy.run(run_step, args=(data,))\n    File \"/Users/gpalazzo/anaconda3/envs/msc/lib/python3.8/site-packages/keras/engine/training.py\", line 1249, in run_step  **\n        outputs = model.train_step(data)\n    File \"/Users/gpalazzo/anaconda3/envs/msc/lib/python3.8/site-packages/keras/engine/training.py\", line 1050, in train_step\n        y_pred = self(x, training=True)\n    File \"/Users/gpalazzo/anaconda3/envs/msc/lib/python3.8/site-packages/keras/utils/traceback_utils.py\", line 70, in error_handler\n        raise e.with_traceback(filtered_tb) from None\n    File \"/Users/gpalazzo/anaconda3/envs/msc/lib/python3.8/site-packages/keras/engine/input_spec.py\", line 298, in assert_input_compatibility\n        raise ValueError(\n\n    ValueError: Input 0 of layer \"sequential_30\" is incompatible with the layer: expected shape=(None, 1, 30), found shape=(16, 30)\n\n\n--------------------------------------------------------------------------------\n1 fits failed with the following error:\nTraceback (most recent call last):\n  File \"/Users/gpalazzo/anaconda3/envs/msc/lib/python3.8/site-packages/sklearn/model_selection/_validation.py\", line 686, in _fit_and_score\n    estimator.fit(X_train, y_train, **fit_params)\n  File \"/Users/gpalazzo/anaconda3/envs/msc/lib/python3.8/site-packages/keras/wrappers/scikit_learn.py\", line 248, in fit\n    return super().fit(x, y, **kwargs)\n  File \"/Users/gpalazzo/anaconda3/envs/msc/lib/python3.8/site-packages/keras/wrappers/scikit_learn.py\", line 175, in fit\n    history = self.model.fit(x, y, **fit_args)\n  File \"/Users/gpalazzo/anaconda3/envs/msc/lib/python3.8/site-packages/keras/utils/traceback_utils.py\", line 70, in error_handler\n    raise e.with_traceback(filtered_tb) from None\n  File \"/var/folders/dv/bgkf3r6s72j37pb4gm7dxtrr0000gn/T/__autograph_generated_filembb5nbmh.py\", line 15, in tf__train_function\n    retval_ = ag__.converted_call(ag__.ld(step_function), (ag__.ld(self), ag__.ld(iterator)), None, fscope)\nValueError: in user code:\n\n    File \"/Users/gpalazzo/anaconda3/envs/msc/lib/python3.8/site-packages/keras/engine/training.py\", line 1284, in train_function  *\n        return step_function(self, iterator)\n    File \"/Users/gpalazzo/anaconda3/envs/msc/lib/python3.8/site-packages/keras/engine/training.py\", line 1268, in step_function  **\n        outputs = model.distribute_strategy.run(run_step, args=(data,))\n    File \"/Users/gpalazzo/anaconda3/envs/msc/lib/python3.8/site-packages/keras/engine/training.py\", line 1249, in run_step  **\n        outputs = model.train_step(data)\n    File \"/Users/gpalazzo/anaconda3/envs/msc/lib/python3.8/site-packages/keras/engine/training.py\", line 1050, in train_step\n        y_pred = self(x, training=True)\n    File \"/Users/gpalazzo/anaconda3/envs/msc/lib/python3.8/site-packages/keras/utils/traceback_utils.py\", line 70, in error_handler\n        raise e.with_traceback(filtered_tb) from None\n    File \"/Users/gpalazzo/anaconda3/envs/msc/lib/python3.8/site-packages/keras/engine/input_spec.py\", line 298, in assert_input_compatibility\n        raise ValueError(\n\n    ValueError: Input 0 of layer \"sequential_31\" is incompatible with the layer: expected shape=(None, 1, 30), found shape=(16, 30)\n\n\n--------------------------------------------------------------------------------\n1 fits failed with the following error:\nTraceback (most recent call last):\n  File \"/Users/gpalazzo/anaconda3/envs/msc/lib/python3.8/site-packages/sklearn/model_selection/_validation.py\", line 686, in _fit_and_score\n    estimator.fit(X_train, y_train, **fit_params)\n  File \"/Users/gpalazzo/anaconda3/envs/msc/lib/python3.8/site-packages/keras/wrappers/scikit_learn.py\", line 248, in fit\n    return super().fit(x, y, **kwargs)\n  File \"/Users/gpalazzo/anaconda3/envs/msc/lib/python3.8/site-packages/keras/wrappers/scikit_learn.py\", line 175, in fit\n    history = self.model.fit(x, y, **fit_args)\n  File \"/Users/gpalazzo/anaconda3/envs/msc/lib/python3.8/site-packages/keras/utils/traceback_utils.py\", line 70, in error_handler\n    raise e.with_traceback(filtered_tb) from None\n  File \"/var/folders/dv/bgkf3r6s72j37pb4gm7dxtrr0000gn/T/__autograph_generated_filembb5nbmh.py\", line 15, in tf__train_function\n    retval_ = ag__.converted_call(ag__.ld(step_function), (ag__.ld(self), ag__.ld(iterator)), None, fscope)\nValueError: in user code:\n\n    File \"/Users/gpalazzo/anaconda3/envs/msc/lib/python3.8/site-packages/keras/engine/training.py\", line 1284, in train_function  *\n        return step_function(self, iterator)\n    File \"/Users/gpalazzo/anaconda3/envs/msc/lib/python3.8/site-packages/keras/engine/training.py\", line 1268, in step_function  **\n        outputs = model.distribute_strategy.run(run_step, args=(data,))\n    File \"/Users/gpalazzo/anaconda3/envs/msc/lib/python3.8/site-packages/keras/engine/training.py\", line 1249, in run_step  **\n        outputs = model.train_step(data)\n    File \"/Users/gpalazzo/anaconda3/envs/msc/lib/python3.8/site-packages/keras/engine/training.py\", line 1050, in train_step\n        y_pred = self(x, training=True)\n    File \"/Users/gpalazzo/anaconda3/envs/msc/lib/python3.8/site-packages/keras/utils/traceback_utils.py\", line 70, in error_handler\n        raise e.with_traceback(filtered_tb) from None\n    File \"/Users/gpalazzo/anaconda3/envs/msc/lib/python3.8/site-packages/keras/engine/input_spec.py\", line 298, in assert_input_compatibility\n        raise ValueError(\n\n    ValueError: Input 0 of layer \"sequential_32\" is incompatible with the layer: expected shape=(None, 1, 30), found shape=(16, 30)\n\n\n--------------------------------------------------------------------------------\n1 fits failed with the following error:\nTraceback (most recent call last):\n  File \"/Users/gpalazzo/anaconda3/envs/msc/lib/python3.8/site-packages/sklearn/model_selection/_validation.py\", line 686, in _fit_and_score\n    estimator.fit(X_train, y_train, **fit_params)\n  File \"/Users/gpalazzo/anaconda3/envs/msc/lib/python3.8/site-packages/keras/wrappers/scikit_learn.py\", line 248, in fit\n    return super().fit(x, y, **kwargs)\n  File \"/Users/gpalazzo/anaconda3/envs/msc/lib/python3.8/site-packages/keras/wrappers/scikit_learn.py\", line 175, in fit\n    history = self.model.fit(x, y, **fit_args)\n  File \"/Users/gpalazzo/anaconda3/envs/msc/lib/python3.8/site-packages/keras/utils/traceback_utils.py\", line 70, in error_handler\n    raise e.with_traceback(filtered_tb) from None\n  File \"/var/folders/dv/bgkf3r6s72j37pb4gm7dxtrr0000gn/T/__autograph_generated_filembb5nbmh.py\", line 15, in tf__train_function\n    retval_ = ag__.converted_call(ag__.ld(step_function), (ag__.ld(self), ag__.ld(iterator)), None, fscope)\nValueError: in user code:\n\n    File \"/Users/gpalazzo/anaconda3/envs/msc/lib/python3.8/site-packages/keras/engine/training.py\", line 1284, in train_function  *\n        return step_function(self, iterator)\n    File \"/Users/gpalazzo/anaconda3/envs/msc/lib/python3.8/site-packages/keras/engine/training.py\", line 1268, in step_function  **\n        outputs = model.distribute_strategy.run(run_step, args=(data,))\n    File \"/Users/gpalazzo/anaconda3/envs/msc/lib/python3.8/site-packages/keras/engine/training.py\", line 1249, in run_step  **\n        outputs = model.train_step(data)\n    File \"/Users/gpalazzo/anaconda3/envs/msc/lib/python3.8/site-packages/keras/engine/training.py\", line 1050, in train_step\n        y_pred = self(x, training=True)\n    File \"/Users/gpalazzo/anaconda3/envs/msc/lib/python3.8/site-packages/keras/utils/traceback_utils.py\", line 70, in error_handler\n        raise e.with_traceback(filtered_tb) from None\n    File \"/Users/gpalazzo/anaconda3/envs/msc/lib/python3.8/site-packages/keras/engine/input_spec.py\", line 298, in assert_input_compatibility\n        raise ValueError(\n\n    ValueError: Input 0 of layer \"sequential_33\" is incompatible with the layer: expected shape=(None, 1, 30), found shape=(16, 30)\n\n\n--------------------------------------------------------------------------------\n1 fits failed with the following error:\nTraceback (most recent call last):\n  File \"/Users/gpalazzo/anaconda3/envs/msc/lib/python3.8/site-packages/sklearn/model_selection/_validation.py\", line 686, in _fit_and_score\n    estimator.fit(X_train, y_train, **fit_params)\n  File \"/Users/gpalazzo/anaconda3/envs/msc/lib/python3.8/site-packages/keras/wrappers/scikit_learn.py\", line 248, in fit\n    return super().fit(x, y, **kwargs)\n  File \"/Users/gpalazzo/anaconda3/envs/msc/lib/python3.8/site-packages/keras/wrappers/scikit_learn.py\", line 175, in fit\n    history = self.model.fit(x, y, **fit_args)\n  File \"/Users/gpalazzo/anaconda3/envs/msc/lib/python3.8/site-packages/keras/utils/traceback_utils.py\", line 70, in error_handler\n    raise e.with_traceback(filtered_tb) from None\n  File \"/var/folders/dv/bgkf3r6s72j37pb4gm7dxtrr0000gn/T/__autograph_generated_filembb5nbmh.py\", line 15, in tf__train_function\n    retval_ = ag__.converted_call(ag__.ld(step_function), (ag__.ld(self), ag__.ld(iterator)), None, fscope)\nValueError: in user code:\n\n    File \"/Users/gpalazzo/anaconda3/envs/msc/lib/python3.8/site-packages/keras/engine/training.py\", line 1284, in train_function  *\n        return step_function(self, iterator)\n    File \"/Users/gpalazzo/anaconda3/envs/msc/lib/python3.8/site-packages/keras/engine/training.py\", line 1268, in step_function  **\n        outputs = model.distribute_strategy.run(run_step, args=(data,))\n    File \"/Users/gpalazzo/anaconda3/envs/msc/lib/python3.8/site-packages/keras/engine/training.py\", line 1249, in run_step  **\n        outputs = model.train_step(data)\n    File \"/Users/gpalazzo/anaconda3/envs/msc/lib/python3.8/site-packages/keras/engine/training.py\", line 1050, in train_step\n        y_pred = self(x, training=True)\n    File \"/Users/gpalazzo/anaconda3/envs/msc/lib/python3.8/site-packages/keras/utils/traceback_utils.py\", line 70, in error_handler\n        raise e.with_traceback(filtered_tb) from None\n    File \"/Users/gpalazzo/anaconda3/envs/msc/lib/python3.8/site-packages/keras/engine/input_spec.py\", line 298, in assert_input_compatibility\n        raise ValueError(\n\n    ValueError: Input 0 of layer \"sequential_34\" is incompatible with the layer: expected shape=(None, 1, 30), found shape=(16, 30)\n\n\n--------------------------------------------------------------------------------\n1 fits failed with the following error:\nTraceback (most recent call last):\n  File \"/Users/gpalazzo/anaconda3/envs/msc/lib/python3.8/site-packages/sklearn/model_selection/_validation.py\", line 686, in _fit_and_score\n    estimator.fit(X_train, y_train, **fit_params)\n  File \"/Users/gpalazzo/anaconda3/envs/msc/lib/python3.8/site-packages/keras/wrappers/scikit_learn.py\", line 248, in fit\n    return super().fit(x, y, **kwargs)\n  File \"/Users/gpalazzo/anaconda3/envs/msc/lib/python3.8/site-packages/keras/wrappers/scikit_learn.py\", line 175, in fit\n    history = self.model.fit(x, y, **fit_args)\n  File \"/Users/gpalazzo/anaconda3/envs/msc/lib/python3.8/site-packages/keras/utils/traceback_utils.py\", line 70, in error_handler\n    raise e.with_traceback(filtered_tb) from None\n  File \"/var/folders/dv/bgkf3r6s72j37pb4gm7dxtrr0000gn/T/__autograph_generated_filembb5nbmh.py\", line 15, in tf__train_function\n    retval_ = ag__.converted_call(ag__.ld(step_function), (ag__.ld(self), ag__.ld(iterator)), None, fscope)\nValueError: in user code:\n\n    File \"/Users/gpalazzo/anaconda3/envs/msc/lib/python3.8/site-packages/keras/engine/training.py\", line 1284, in train_function  *\n        return step_function(self, iterator)\n    File \"/Users/gpalazzo/anaconda3/envs/msc/lib/python3.8/site-packages/keras/engine/training.py\", line 1268, in step_function  **\n        outputs = model.distribute_strategy.run(run_step, args=(data,))\n    File \"/Users/gpalazzo/anaconda3/envs/msc/lib/python3.8/site-packages/keras/engine/training.py\", line 1249, in run_step  **\n        outputs = model.train_step(data)\n    File \"/Users/gpalazzo/anaconda3/envs/msc/lib/python3.8/site-packages/keras/engine/training.py\", line 1050, in train_step\n        y_pred = self(x, training=True)\n    File \"/Users/gpalazzo/anaconda3/envs/msc/lib/python3.8/site-packages/keras/utils/traceback_utils.py\", line 70, in error_handler\n        raise e.with_traceback(filtered_tb) from None\n    File \"/Users/gpalazzo/anaconda3/envs/msc/lib/python3.8/site-packages/keras/engine/input_spec.py\", line 298, in assert_input_compatibility\n        raise ValueError(\n\n    ValueError: Input 0 of layer \"sequential_35\" is incompatible with the layer: expected shape=(None, 1, 30), found shape=(16, 30)\n\n",
     "output_type": "error",
     "traceback": [
      "\u001b[0;31m---------------------------------------------------------------------------\u001b[0m",
      "\u001b[0;31mValueError\u001b[0m                                Traceback (most recent call last)",
      "Cell \u001b[0;32mIn[21], line 72\u001b[0m\n\u001b[1;32m     69\u001b[0m model \u001b[39m=\u001b[39m KerasClassifier(build_fn\u001b[39m=\u001b[39mcreate_model_lstm, epochs\u001b[39m=\u001b[39m\u001b[39m10\u001b[39m, verbose\u001b[39m=\u001b[39m\u001b[39m1\u001b[39m)\n\u001b[1;32m     71\u001b[0m grid \u001b[39m=\u001b[39m GridSearchCV(estimator\u001b[39m=\u001b[39mmodel, param_grid\u001b[39m=\u001b[39mlstm_model_params, n_jobs\u001b[39m=\u001b[39m\u001b[39m1\u001b[39m, cv\u001b[39m=\u001b[39m\u001b[39m3\u001b[39m)\n\u001b[0;32m---> 72\u001b[0m grid_result \u001b[39m=\u001b[39m grid\u001b[39m.\u001b[39;49mfit(X_train, y_train)\n\u001b[1;32m     74\u001b[0m \u001b[39mprint\u001b[39m(\u001b[39m\"\u001b[39m\u001b[39mBest accuracy of: \u001b[39m\u001b[39m%f\u001b[39;00m\u001b[39m using \u001b[39m\u001b[39m%s\u001b[39;00m\u001b[39m\"\u001b[39m \u001b[39m%\u001b[39m (grid_result\u001b[39m.\u001b[39mbest_score_, \n\u001b[1;32m     75\u001b[0m                                          grid_result\u001b[39m.\u001b[39mbest_params_))\n",
      "File \u001b[0;32m~/anaconda3/envs/msc/lib/python3.8/site-packages/sklearn/model_selection/_search.py:874\u001b[0m, in \u001b[0;36mBaseSearchCV.fit\u001b[0;34m(self, X, y, groups, **fit_params)\u001b[0m\n\u001b[1;32m    868\u001b[0m     results \u001b[39m=\u001b[39m \u001b[39mself\u001b[39m\u001b[39m.\u001b[39m_format_results(\n\u001b[1;32m    869\u001b[0m         all_candidate_params, n_splits, all_out, all_more_results\n\u001b[1;32m    870\u001b[0m     )\n\u001b[1;32m    872\u001b[0m     \u001b[39mreturn\u001b[39;00m results\n\u001b[0;32m--> 874\u001b[0m \u001b[39mself\u001b[39;49m\u001b[39m.\u001b[39;49m_run_search(evaluate_candidates)\n\u001b[1;32m    876\u001b[0m \u001b[39m# multimetric is determined here because in the case of a callable\u001b[39;00m\n\u001b[1;32m    877\u001b[0m \u001b[39m# self.scoring the return type is only known after calling\u001b[39;00m\n\u001b[1;32m    878\u001b[0m first_test_score \u001b[39m=\u001b[39m all_out[\u001b[39m0\u001b[39m][\u001b[39m\"\u001b[39m\u001b[39mtest_scores\u001b[39m\u001b[39m\"\u001b[39m]\n",
      "File \u001b[0;32m~/anaconda3/envs/msc/lib/python3.8/site-packages/sklearn/model_selection/_search.py:1388\u001b[0m, in \u001b[0;36mGridSearchCV._run_search\u001b[0;34m(self, evaluate_candidates)\u001b[0m\n\u001b[1;32m   1386\u001b[0m \u001b[39mdef\u001b[39;00m \u001b[39m_run_search\u001b[39m(\u001b[39mself\u001b[39m, evaluate_candidates):\n\u001b[1;32m   1387\u001b[0m \u001b[39m    \u001b[39m\u001b[39m\"\"\"Search all candidates in param_grid\"\"\"\u001b[39;00m\n\u001b[0;32m-> 1388\u001b[0m     evaluate_candidates(ParameterGrid(\u001b[39mself\u001b[39;49m\u001b[39m.\u001b[39;49mparam_grid))\n",
      "File \u001b[0;32m~/anaconda3/envs/msc/lib/python3.8/site-packages/sklearn/model_selection/_search.py:851\u001b[0m, in \u001b[0;36mBaseSearchCV.fit.<locals>.evaluate_candidates\u001b[0;34m(candidate_params, cv, more_results)\u001b[0m\n\u001b[1;32m    844\u001b[0m \u001b[39melif\u001b[39;00m \u001b[39mlen\u001b[39m(out) \u001b[39m!=\u001b[39m n_candidates \u001b[39m*\u001b[39m n_splits:\n\u001b[1;32m    845\u001b[0m     \u001b[39mraise\u001b[39;00m \u001b[39mValueError\u001b[39;00m(\n\u001b[1;32m    846\u001b[0m         \u001b[39m\"\u001b[39m\u001b[39mcv.split and cv.get_n_splits returned \u001b[39m\u001b[39m\"\u001b[39m\n\u001b[1;32m    847\u001b[0m         \u001b[39m\"\u001b[39m\u001b[39minconsistent results. Expected \u001b[39m\u001b[39m{}\u001b[39;00m\u001b[39m \u001b[39m\u001b[39m\"\u001b[39m\n\u001b[1;32m    848\u001b[0m         \u001b[39m\"\u001b[39m\u001b[39msplits, got \u001b[39m\u001b[39m{}\u001b[39;00m\u001b[39m\"\u001b[39m\u001b[39m.\u001b[39mformat(n_splits, \u001b[39mlen\u001b[39m(out) \u001b[39m/\u001b[39m\u001b[39m/\u001b[39m n_candidates)\n\u001b[1;32m    849\u001b[0m     )\n\u001b[0;32m--> 851\u001b[0m _warn_or_raise_about_fit_failures(out, \u001b[39mself\u001b[39;49m\u001b[39m.\u001b[39;49merror_score)\n\u001b[1;32m    853\u001b[0m \u001b[39m# For callable self.scoring, the return type is only know after\u001b[39;00m\n\u001b[1;32m    854\u001b[0m \u001b[39m# calling. If the return type is a dictionary, the error scores\u001b[39;00m\n\u001b[1;32m    855\u001b[0m \u001b[39m# can now be inserted with the correct key. The type checking\u001b[39;00m\n\u001b[1;32m    856\u001b[0m \u001b[39m# of out will be done in `_insert_error_scores`.\u001b[39;00m\n\u001b[1;32m    857\u001b[0m \u001b[39mif\u001b[39;00m \u001b[39mcallable\u001b[39m(\u001b[39mself\u001b[39m\u001b[39m.\u001b[39mscoring):\n",
      "File \u001b[0;32m~/anaconda3/envs/msc/lib/python3.8/site-packages/sklearn/model_selection/_validation.py:367\u001b[0m, in \u001b[0;36m_warn_or_raise_about_fit_failures\u001b[0;34m(results, error_score)\u001b[0m\n\u001b[1;32m    360\u001b[0m \u001b[39mif\u001b[39;00m num_failed_fits \u001b[39m==\u001b[39m num_fits:\n\u001b[1;32m    361\u001b[0m     all_fits_failed_message \u001b[39m=\u001b[39m (\n\u001b[1;32m    362\u001b[0m         \u001b[39mf\u001b[39m\u001b[39m\"\u001b[39m\u001b[39m\\n\u001b[39;00m\u001b[39mAll the \u001b[39m\u001b[39m{\u001b[39;00mnum_fits\u001b[39m}\u001b[39;00m\u001b[39m fits failed.\u001b[39m\u001b[39m\\n\u001b[39;00m\u001b[39m\"\u001b[39m\n\u001b[1;32m    363\u001b[0m         \u001b[39m\"\u001b[39m\u001b[39mIt is very likely that your model is misconfigured.\u001b[39m\u001b[39m\\n\u001b[39;00m\u001b[39m\"\u001b[39m\n\u001b[1;32m    364\u001b[0m         \u001b[39m\"\u001b[39m\u001b[39mYou can try to debug the error by setting error_score=\u001b[39m\u001b[39m'\u001b[39m\u001b[39mraise\u001b[39m\u001b[39m'\u001b[39m\u001b[39m.\u001b[39m\u001b[39m\\n\u001b[39;00m\u001b[39m\\n\u001b[39;00m\u001b[39m\"\u001b[39m\n\u001b[1;32m    365\u001b[0m         \u001b[39mf\u001b[39m\u001b[39m\"\u001b[39m\u001b[39mBelow are more details about the failures:\u001b[39m\u001b[39m\\n\u001b[39;00m\u001b[39m{\u001b[39;00mfit_errors_summary\u001b[39m}\u001b[39;00m\u001b[39m\"\u001b[39m\n\u001b[1;32m    366\u001b[0m     )\n\u001b[0;32m--> 367\u001b[0m     \u001b[39mraise\u001b[39;00m \u001b[39mValueError\u001b[39;00m(all_fits_failed_message)\n\u001b[1;32m    369\u001b[0m \u001b[39melse\u001b[39;00m:\n\u001b[1;32m    370\u001b[0m     some_fits_failed_message \u001b[39m=\u001b[39m (\n\u001b[1;32m    371\u001b[0m         \u001b[39mf\u001b[39m\u001b[39m\"\u001b[39m\u001b[39m\\n\u001b[39;00m\u001b[39m{\u001b[39;00mnum_failed_fits\u001b[39m}\u001b[39;00m\u001b[39m fits failed out of a total of \u001b[39m\u001b[39m{\u001b[39;00mnum_fits\u001b[39m}\u001b[39;00m\u001b[39m.\u001b[39m\u001b[39m\\n\u001b[39;00m\u001b[39m\"\u001b[39m\n\u001b[1;32m    372\u001b[0m         \u001b[39m\"\u001b[39m\u001b[39mThe score on these train-test partitions for these parameters\u001b[39m\u001b[39m\"\u001b[39m\n\u001b[0;32m   (...)\u001b[0m\n\u001b[1;32m    376\u001b[0m         \u001b[39mf\u001b[39m\u001b[39m\"\u001b[39m\u001b[39mBelow are more details about the failures:\u001b[39m\u001b[39m\\n\u001b[39;00m\u001b[39m{\u001b[39;00mfit_errors_summary\u001b[39m}\u001b[39;00m\u001b[39m\"\u001b[39m\n\u001b[1;32m    377\u001b[0m     )\n",
      "\u001b[0;31mValueError\u001b[0m: \nAll the 18 fits failed.\nIt is very likely that your model is misconfigured.\nYou can try to debug the error by setting error_score='raise'.\n\nBelow are more details about the failures:\n--------------------------------------------------------------------------------\n1 fits failed with the following error:\nTraceback (most recent call last):\n  File \"/Users/gpalazzo/anaconda3/envs/msc/lib/python3.8/site-packages/sklearn/model_selection/_validation.py\", line 686, in _fit_and_score\n    estimator.fit(X_train, y_train, **fit_params)\n  File \"/Users/gpalazzo/anaconda3/envs/msc/lib/python3.8/site-packages/keras/wrappers/scikit_learn.py\", line 248, in fit\n    return super().fit(x, y, **kwargs)\n  File \"/Users/gpalazzo/anaconda3/envs/msc/lib/python3.8/site-packages/keras/wrappers/scikit_learn.py\", line 175, in fit\n    history = self.model.fit(x, y, **fit_args)\n  File \"/Users/gpalazzo/anaconda3/envs/msc/lib/python3.8/site-packages/keras/utils/traceback_utils.py\", line 70, in error_handler\n    raise e.with_traceback(filtered_tb) from None\n  File \"/var/folders/dv/bgkf3r6s72j37pb4gm7dxtrr0000gn/T/__autograph_generated_filembb5nbmh.py\", line 15, in tf__train_function\n    retval_ = ag__.converted_call(ag__.ld(step_function), (ag__.ld(self), ag__.ld(iterator)), None, fscope)\nValueError: in user code:\n\n    File \"/Users/gpalazzo/anaconda3/envs/msc/lib/python3.8/site-packages/keras/engine/training.py\", line 1284, in train_function  *\n        return step_function(self, iterator)\n    File \"/Users/gpalazzo/anaconda3/envs/msc/lib/python3.8/site-packages/keras/engine/training.py\", line 1268, in step_function  **\n        outputs = model.distribute_strategy.run(run_step, args=(data,))\n    File \"/Users/gpalazzo/anaconda3/envs/msc/lib/python3.8/site-packages/keras/engine/training.py\", line 1249, in run_step  **\n        outputs = model.train_step(data)\n    File \"/Users/gpalazzo/anaconda3/envs/msc/lib/python3.8/site-packages/keras/engine/training.py\", line 1050, in train_step\n        y_pred = self(x, training=True)\n    File \"/Users/gpalazzo/anaconda3/envs/msc/lib/python3.8/site-packages/keras/utils/traceback_utils.py\", line 70, in error_handler\n        raise e.with_traceback(filtered_tb) from None\n    File \"/Users/gpalazzo/anaconda3/envs/msc/lib/python3.8/site-packages/keras/engine/input_spec.py\", line 298, in assert_input_compatibility\n        raise ValueError(\n\n    ValueError: Input 0 of layer \"sequential_18\" is incompatible with the layer: expected shape=(None, 1, 30), found shape=(4, 30)\n\n\n--------------------------------------------------------------------------------\n1 fits failed with the following error:\nTraceback (most recent call last):\n  File \"/Users/gpalazzo/anaconda3/envs/msc/lib/python3.8/site-packages/sklearn/model_selection/_validation.py\", line 686, in _fit_and_score\n    estimator.fit(X_train, y_train, **fit_params)\n  File \"/Users/gpalazzo/anaconda3/envs/msc/lib/python3.8/site-packages/keras/wrappers/scikit_learn.py\", line 248, in fit\n    return super().fit(x, y, **kwargs)\n  File \"/Users/gpalazzo/anaconda3/envs/msc/lib/python3.8/site-packages/keras/wrappers/scikit_learn.py\", line 175, in fit\n    history = self.model.fit(x, y, **fit_args)\n  File \"/Users/gpalazzo/anaconda3/envs/msc/lib/python3.8/site-packages/keras/utils/traceback_utils.py\", line 70, in error_handler\n    raise e.with_traceback(filtered_tb) from None\n  File \"/var/folders/dv/bgkf3r6s72j37pb4gm7dxtrr0000gn/T/__autograph_generated_filembb5nbmh.py\", line 15, in tf__train_function\n    retval_ = ag__.converted_call(ag__.ld(step_function), (ag__.ld(self), ag__.ld(iterator)), None, fscope)\nValueError: in user code:\n\n    File \"/Users/gpalazzo/anaconda3/envs/msc/lib/python3.8/site-packages/keras/engine/training.py\", line 1284, in train_function  *\n        return step_function(self, iterator)\n    File \"/Users/gpalazzo/anaconda3/envs/msc/lib/python3.8/site-packages/keras/engine/training.py\", line 1268, in step_function  **\n        outputs = model.distribute_strategy.run(run_step, args=(data,))\n    File \"/Users/gpalazzo/anaconda3/envs/msc/lib/python3.8/site-packages/keras/engine/training.py\", line 1249, in run_step  **\n        outputs = model.train_step(data)\n    File \"/Users/gpalazzo/anaconda3/envs/msc/lib/python3.8/site-packages/keras/engine/training.py\", line 1050, in train_step\n        y_pred = self(x, training=True)\n    File \"/Users/gpalazzo/anaconda3/envs/msc/lib/python3.8/site-packages/keras/utils/traceback_utils.py\", line 70, in error_handler\n        raise e.with_traceback(filtered_tb) from None\n    File \"/Users/gpalazzo/anaconda3/envs/msc/lib/python3.8/site-packages/keras/engine/input_spec.py\", line 298, in assert_input_compatibility\n        raise ValueError(\n\n    ValueError: Input 0 of layer \"sequential_19\" is incompatible with the layer: expected shape=(None, 1, 30), found shape=(4, 30)\n\n\n--------------------------------------------------------------------------------\n1 fits failed with the following error:\nTraceback (most recent call last):\n  File \"/Users/gpalazzo/anaconda3/envs/msc/lib/python3.8/site-packages/sklearn/model_selection/_validation.py\", line 686, in _fit_and_score\n    estimator.fit(X_train, y_train, **fit_params)\n  File \"/Users/gpalazzo/anaconda3/envs/msc/lib/python3.8/site-packages/keras/wrappers/scikit_learn.py\", line 248, in fit\n    return super().fit(x, y, **kwargs)\n  File \"/Users/gpalazzo/anaconda3/envs/msc/lib/python3.8/site-packages/keras/wrappers/scikit_learn.py\", line 175, in fit\n    history = self.model.fit(x, y, **fit_args)\n  File \"/Users/gpalazzo/anaconda3/envs/msc/lib/python3.8/site-packages/keras/utils/traceback_utils.py\", line 70, in error_handler\n    raise e.with_traceback(filtered_tb) from None\n  File \"/var/folders/dv/bgkf3r6s72j37pb4gm7dxtrr0000gn/T/__autograph_generated_filembb5nbmh.py\", line 15, in tf__train_function\n    retval_ = ag__.converted_call(ag__.ld(step_function), (ag__.ld(self), ag__.ld(iterator)), None, fscope)\nValueError: in user code:\n\n    File \"/Users/gpalazzo/anaconda3/envs/msc/lib/python3.8/site-packages/keras/engine/training.py\", line 1284, in train_function  *\n        return step_function(self, iterator)\n    File \"/Users/gpalazzo/anaconda3/envs/msc/lib/python3.8/site-packages/keras/engine/training.py\", line 1268, in step_function  **\n        outputs = model.distribute_strategy.run(run_step, args=(data,))\n    File \"/Users/gpalazzo/anaconda3/envs/msc/lib/python3.8/site-packages/keras/engine/training.py\", line 1249, in run_step  **\n        outputs = model.train_step(data)\n    File \"/Users/gpalazzo/anaconda3/envs/msc/lib/python3.8/site-packages/keras/engine/training.py\", line 1050, in train_step\n        y_pred = self(x, training=True)\n    File \"/Users/gpalazzo/anaconda3/envs/msc/lib/python3.8/site-packages/keras/utils/traceback_utils.py\", line 70, in error_handler\n        raise e.with_traceback(filtered_tb) from None\n    File \"/Users/gpalazzo/anaconda3/envs/msc/lib/python3.8/site-packages/keras/engine/input_spec.py\", line 298, in assert_input_compatibility\n        raise ValueError(\n\n    ValueError: Input 0 of layer \"sequential_20\" is incompatible with the layer: expected shape=(None, 1, 30), found shape=(4, 30)\n\n\n--------------------------------------------------------------------------------\n1 fits failed with the following error:\nTraceback (most recent call last):\n  File \"/Users/gpalazzo/anaconda3/envs/msc/lib/python3.8/site-packages/sklearn/model_selection/_validation.py\", line 686, in _fit_and_score\n    estimator.fit(X_train, y_train, **fit_params)\n  File \"/Users/gpalazzo/anaconda3/envs/msc/lib/python3.8/site-packages/keras/wrappers/scikit_learn.py\", line 248, in fit\n    return super().fit(x, y, **kwargs)\n  File \"/Users/gpalazzo/anaconda3/envs/msc/lib/python3.8/site-packages/keras/wrappers/scikit_learn.py\", line 175, in fit\n    history = self.model.fit(x, y, **fit_args)\n  File \"/Users/gpalazzo/anaconda3/envs/msc/lib/python3.8/site-packages/keras/utils/traceback_utils.py\", line 70, in error_handler\n    raise e.with_traceback(filtered_tb) from None\n  File \"/var/folders/dv/bgkf3r6s72j37pb4gm7dxtrr0000gn/T/__autograph_generated_filembb5nbmh.py\", line 15, in tf__train_function\n    retval_ = ag__.converted_call(ag__.ld(step_function), (ag__.ld(self), ag__.ld(iterator)), None, fscope)\nValueError: in user code:\n\n    File \"/Users/gpalazzo/anaconda3/envs/msc/lib/python3.8/site-packages/keras/engine/training.py\", line 1284, in train_function  *\n        return step_function(self, iterator)\n    File \"/Users/gpalazzo/anaconda3/envs/msc/lib/python3.8/site-packages/keras/engine/training.py\", line 1268, in step_function  **\n        outputs = model.distribute_strategy.run(run_step, args=(data,))\n    File \"/Users/gpalazzo/anaconda3/envs/msc/lib/python3.8/site-packages/keras/engine/training.py\", line 1249, in run_step  **\n        outputs = model.train_step(data)\n    File \"/Users/gpalazzo/anaconda3/envs/msc/lib/python3.8/site-packages/keras/engine/training.py\", line 1050, in train_step\n        y_pred = self(x, training=True)\n    File \"/Users/gpalazzo/anaconda3/envs/msc/lib/python3.8/site-packages/keras/utils/traceback_utils.py\", line 70, in error_handler\n        raise e.with_traceback(filtered_tb) from None\n    File \"/Users/gpalazzo/anaconda3/envs/msc/lib/python3.8/site-packages/keras/engine/input_spec.py\", line 298, in assert_input_compatibility\n        raise ValueError(\n\n    ValueError: Input 0 of layer \"sequential_21\" is incompatible with the layer: expected shape=(None, 1, 30), found shape=(4, 30)\n\n\n--------------------------------------------------------------------------------\n1 fits failed with the following error:\nTraceback (most recent call last):\n  File \"/Users/gpalazzo/anaconda3/envs/msc/lib/python3.8/site-packages/sklearn/model_selection/_validation.py\", line 686, in _fit_and_score\n    estimator.fit(X_train, y_train, **fit_params)\n  File \"/Users/gpalazzo/anaconda3/envs/msc/lib/python3.8/site-packages/keras/wrappers/scikit_learn.py\", line 248, in fit\n    return super().fit(x, y, **kwargs)\n  File \"/Users/gpalazzo/anaconda3/envs/msc/lib/python3.8/site-packages/keras/wrappers/scikit_learn.py\", line 175, in fit\n    history = self.model.fit(x, y, **fit_args)\n  File \"/Users/gpalazzo/anaconda3/envs/msc/lib/python3.8/site-packages/keras/utils/traceback_utils.py\", line 70, in error_handler\n    raise e.with_traceback(filtered_tb) from None\n  File \"/var/folders/dv/bgkf3r6s72j37pb4gm7dxtrr0000gn/T/__autograph_generated_filembb5nbmh.py\", line 15, in tf__train_function\n    retval_ = ag__.converted_call(ag__.ld(step_function), (ag__.ld(self), ag__.ld(iterator)), None, fscope)\nValueError: in user code:\n\n    File \"/Users/gpalazzo/anaconda3/envs/msc/lib/python3.8/site-packages/keras/engine/training.py\", line 1284, in train_function  *\n        return step_function(self, iterator)\n    File \"/Users/gpalazzo/anaconda3/envs/msc/lib/python3.8/site-packages/keras/engine/training.py\", line 1268, in step_function  **\n        outputs = model.distribute_strategy.run(run_step, args=(data,))\n    File \"/Users/gpalazzo/anaconda3/envs/msc/lib/python3.8/site-packages/keras/engine/training.py\", line 1249, in run_step  **\n        outputs = model.train_step(data)\n    File \"/Users/gpalazzo/anaconda3/envs/msc/lib/python3.8/site-packages/keras/engine/training.py\", line 1050, in train_step\n        y_pred = self(x, training=True)\n    File \"/Users/gpalazzo/anaconda3/envs/msc/lib/python3.8/site-packages/keras/utils/traceback_utils.py\", line 70, in error_handler\n        raise e.with_traceback(filtered_tb) from None\n    File \"/Users/gpalazzo/anaconda3/envs/msc/lib/python3.8/site-packages/keras/engine/input_spec.py\", line 298, in assert_input_compatibility\n        raise ValueError(\n\n    ValueError: Input 0 of layer \"sequential_22\" is incompatible with the layer: expected shape=(None, 1, 30), found shape=(4, 30)\n\n\n--------------------------------------------------------------------------------\n1 fits failed with the following error:\nTraceback (most recent call last):\n  File \"/Users/gpalazzo/anaconda3/envs/msc/lib/python3.8/site-packages/sklearn/model_selection/_validation.py\", line 686, in _fit_and_score\n    estimator.fit(X_train, y_train, **fit_params)\n  File \"/Users/gpalazzo/anaconda3/envs/msc/lib/python3.8/site-packages/keras/wrappers/scikit_learn.py\", line 248, in fit\n    return super().fit(x, y, **kwargs)\n  File \"/Users/gpalazzo/anaconda3/envs/msc/lib/python3.8/site-packages/keras/wrappers/scikit_learn.py\", line 175, in fit\n    history = self.model.fit(x, y, **fit_args)\n  File \"/Users/gpalazzo/anaconda3/envs/msc/lib/python3.8/site-packages/keras/utils/traceback_utils.py\", line 70, in error_handler\n    raise e.with_traceback(filtered_tb) from None\n  File \"/var/folders/dv/bgkf3r6s72j37pb4gm7dxtrr0000gn/T/__autograph_generated_filembb5nbmh.py\", line 15, in tf__train_function\n    retval_ = ag__.converted_call(ag__.ld(step_function), (ag__.ld(self), ag__.ld(iterator)), None, fscope)\nValueError: in user code:\n\n    File \"/Users/gpalazzo/anaconda3/envs/msc/lib/python3.8/site-packages/keras/engine/training.py\", line 1284, in train_function  *\n        return step_function(self, iterator)\n    File \"/Users/gpalazzo/anaconda3/envs/msc/lib/python3.8/site-packages/keras/engine/training.py\", line 1268, in step_function  **\n        outputs = model.distribute_strategy.run(run_step, args=(data,))\n    File \"/Users/gpalazzo/anaconda3/envs/msc/lib/python3.8/site-packages/keras/engine/training.py\", line 1249, in run_step  **\n        outputs = model.train_step(data)\n    File \"/Users/gpalazzo/anaconda3/envs/msc/lib/python3.8/site-packages/keras/engine/training.py\", line 1050, in train_step\n        y_pred = self(x, training=True)\n    File \"/Users/gpalazzo/anaconda3/envs/msc/lib/python3.8/site-packages/keras/utils/traceback_utils.py\", line 70, in error_handler\n        raise e.with_traceback(filtered_tb) from None\n    File \"/Users/gpalazzo/anaconda3/envs/msc/lib/python3.8/site-packages/keras/engine/input_spec.py\", line 298, in assert_input_compatibility\n        raise ValueError(\n\n    ValueError: Input 0 of layer \"sequential_23\" is incompatible with the layer: expected shape=(None, 1, 30), found shape=(4, 30)\n\n\n--------------------------------------------------------------------------------\n1 fits failed with the following error:\nTraceback (most recent call last):\n  File \"/Users/gpalazzo/anaconda3/envs/msc/lib/python3.8/site-packages/sklearn/model_selection/_validation.py\", line 686, in _fit_and_score\n    estimator.fit(X_train, y_train, **fit_params)\n  File \"/Users/gpalazzo/anaconda3/envs/msc/lib/python3.8/site-packages/keras/wrappers/scikit_learn.py\", line 248, in fit\n    return super().fit(x, y, **kwargs)\n  File \"/Users/gpalazzo/anaconda3/envs/msc/lib/python3.8/site-packages/keras/wrappers/scikit_learn.py\", line 175, in fit\n    history = self.model.fit(x, y, **fit_args)\n  File \"/Users/gpalazzo/anaconda3/envs/msc/lib/python3.8/site-packages/keras/utils/traceback_utils.py\", line 70, in error_handler\n    raise e.with_traceback(filtered_tb) from None\n  File \"/var/folders/dv/bgkf3r6s72j37pb4gm7dxtrr0000gn/T/__autograph_generated_filembb5nbmh.py\", line 15, in tf__train_function\n    retval_ = ag__.converted_call(ag__.ld(step_function), (ag__.ld(self), ag__.ld(iterator)), None, fscope)\nValueError: in user code:\n\n    File \"/Users/gpalazzo/anaconda3/envs/msc/lib/python3.8/site-packages/keras/engine/training.py\", line 1284, in train_function  *\n        return step_function(self, iterator)\n    File \"/Users/gpalazzo/anaconda3/envs/msc/lib/python3.8/site-packages/keras/engine/training.py\", line 1268, in step_function  **\n        outputs = model.distribute_strategy.run(run_step, args=(data,))\n    File \"/Users/gpalazzo/anaconda3/envs/msc/lib/python3.8/site-packages/keras/engine/training.py\", line 1249, in run_step  **\n        outputs = model.train_step(data)\n    File \"/Users/gpalazzo/anaconda3/envs/msc/lib/python3.8/site-packages/keras/engine/training.py\", line 1050, in train_step\n        y_pred = self(x, training=True)\n    File \"/Users/gpalazzo/anaconda3/envs/msc/lib/python3.8/site-packages/keras/utils/traceback_utils.py\", line 70, in error_handler\n        raise e.with_traceback(filtered_tb) from None\n    File \"/Users/gpalazzo/anaconda3/envs/msc/lib/python3.8/site-packages/keras/engine/input_spec.py\", line 298, in assert_input_compatibility\n        raise ValueError(\n\n    ValueError: Input 0 of layer \"sequential_24\" is incompatible with the layer: expected shape=(None, 1, 30), found shape=(4, 30)\n\n\n--------------------------------------------------------------------------------\n1 fits failed with the following error:\nTraceback (most recent call last):\n  File \"/Users/gpalazzo/anaconda3/envs/msc/lib/python3.8/site-packages/sklearn/model_selection/_validation.py\", line 686, in _fit_and_score\n    estimator.fit(X_train, y_train, **fit_params)\n  File \"/Users/gpalazzo/anaconda3/envs/msc/lib/python3.8/site-packages/keras/wrappers/scikit_learn.py\", line 248, in fit\n    return super().fit(x, y, **kwargs)\n  File \"/Users/gpalazzo/anaconda3/envs/msc/lib/python3.8/site-packages/keras/wrappers/scikit_learn.py\", line 175, in fit\n    history = self.model.fit(x, y, **fit_args)\n  File \"/Users/gpalazzo/anaconda3/envs/msc/lib/python3.8/site-packages/keras/utils/traceback_utils.py\", line 70, in error_handler\n    raise e.with_traceback(filtered_tb) from None\n  File \"/var/folders/dv/bgkf3r6s72j37pb4gm7dxtrr0000gn/T/__autograph_generated_filembb5nbmh.py\", line 15, in tf__train_function\n    retval_ = ag__.converted_call(ag__.ld(step_function), (ag__.ld(self), ag__.ld(iterator)), None, fscope)\nValueError: in user code:\n\n    File \"/Users/gpalazzo/anaconda3/envs/msc/lib/python3.8/site-packages/keras/engine/training.py\", line 1284, in train_function  *\n        return step_function(self, iterator)\n    File \"/Users/gpalazzo/anaconda3/envs/msc/lib/python3.8/site-packages/keras/engine/training.py\", line 1268, in step_function  **\n        outputs = model.distribute_strategy.run(run_step, args=(data,))\n    File \"/Users/gpalazzo/anaconda3/envs/msc/lib/python3.8/site-packages/keras/engine/training.py\", line 1249, in run_step  **\n        outputs = model.train_step(data)\n    File \"/Users/gpalazzo/anaconda3/envs/msc/lib/python3.8/site-packages/keras/engine/training.py\", line 1050, in train_step\n        y_pred = self(x, training=True)\n    File \"/Users/gpalazzo/anaconda3/envs/msc/lib/python3.8/site-packages/keras/utils/traceback_utils.py\", line 70, in error_handler\n        raise e.with_traceback(filtered_tb) from None\n    File \"/Users/gpalazzo/anaconda3/envs/msc/lib/python3.8/site-packages/keras/engine/input_spec.py\", line 298, in assert_input_compatibility\n        raise ValueError(\n\n    ValueError: Input 0 of layer \"sequential_25\" is incompatible with the layer: expected shape=(None, 1, 30), found shape=(4, 30)\n\n\n--------------------------------------------------------------------------------\n1 fits failed with the following error:\nTraceback (most recent call last):\n  File \"/Users/gpalazzo/anaconda3/envs/msc/lib/python3.8/site-packages/sklearn/model_selection/_validation.py\", line 686, in _fit_and_score\n    estimator.fit(X_train, y_train, **fit_params)\n  File \"/Users/gpalazzo/anaconda3/envs/msc/lib/python3.8/site-packages/keras/wrappers/scikit_learn.py\", line 248, in fit\n    return super().fit(x, y, **kwargs)\n  File \"/Users/gpalazzo/anaconda3/envs/msc/lib/python3.8/site-packages/keras/wrappers/scikit_learn.py\", line 175, in fit\n    history = self.model.fit(x, y, **fit_args)\n  File \"/Users/gpalazzo/anaconda3/envs/msc/lib/python3.8/site-packages/keras/utils/traceback_utils.py\", line 70, in error_handler\n    raise e.with_traceback(filtered_tb) from None\n  File \"/var/folders/dv/bgkf3r6s72j37pb4gm7dxtrr0000gn/T/__autograph_generated_filembb5nbmh.py\", line 15, in tf__train_function\n    retval_ = ag__.converted_call(ag__.ld(step_function), (ag__.ld(self), ag__.ld(iterator)), None, fscope)\nValueError: in user code:\n\n    File \"/Users/gpalazzo/anaconda3/envs/msc/lib/python3.8/site-packages/keras/engine/training.py\", line 1284, in train_function  *\n        return step_function(self, iterator)\n    File \"/Users/gpalazzo/anaconda3/envs/msc/lib/python3.8/site-packages/keras/engine/training.py\", line 1268, in step_function  **\n        outputs = model.distribute_strategy.run(run_step, args=(data,))\n    File \"/Users/gpalazzo/anaconda3/envs/msc/lib/python3.8/site-packages/keras/engine/training.py\", line 1249, in run_step  **\n        outputs = model.train_step(data)\n    File \"/Users/gpalazzo/anaconda3/envs/msc/lib/python3.8/site-packages/keras/engine/training.py\", line 1050, in train_step\n        y_pred = self(x, training=True)\n    File \"/Users/gpalazzo/anaconda3/envs/msc/lib/python3.8/site-packages/keras/utils/traceback_utils.py\", line 70, in error_handler\n        raise e.with_traceback(filtered_tb) from None\n    File \"/Users/gpalazzo/anaconda3/envs/msc/lib/python3.8/site-packages/keras/engine/input_spec.py\", line 298, in assert_input_compatibility\n        raise ValueError(\n\n    ValueError: Input 0 of layer \"sequential_26\" is incompatible with the layer: expected shape=(None, 1, 30), found shape=(4, 30)\n\n\n--------------------------------------------------------------------------------\n1 fits failed with the following error:\nTraceback (most recent call last):\n  File \"/Users/gpalazzo/anaconda3/envs/msc/lib/python3.8/site-packages/sklearn/model_selection/_validation.py\", line 686, in _fit_and_score\n    estimator.fit(X_train, y_train, **fit_params)\n  File \"/Users/gpalazzo/anaconda3/envs/msc/lib/python3.8/site-packages/keras/wrappers/scikit_learn.py\", line 248, in fit\n    return super().fit(x, y, **kwargs)\n  File \"/Users/gpalazzo/anaconda3/envs/msc/lib/python3.8/site-packages/keras/wrappers/scikit_learn.py\", line 175, in fit\n    history = self.model.fit(x, y, **fit_args)\n  File \"/Users/gpalazzo/anaconda3/envs/msc/lib/python3.8/site-packages/keras/utils/traceback_utils.py\", line 70, in error_handler\n    raise e.with_traceback(filtered_tb) from None\n  File \"/var/folders/dv/bgkf3r6s72j37pb4gm7dxtrr0000gn/T/__autograph_generated_filembb5nbmh.py\", line 15, in tf__train_function\n    retval_ = ag__.converted_call(ag__.ld(step_function), (ag__.ld(self), ag__.ld(iterator)), None, fscope)\nValueError: in user code:\n\n    File \"/Users/gpalazzo/anaconda3/envs/msc/lib/python3.8/site-packages/keras/engine/training.py\", line 1284, in train_function  *\n        return step_function(self, iterator)\n    File \"/Users/gpalazzo/anaconda3/envs/msc/lib/python3.8/site-packages/keras/engine/training.py\", line 1268, in step_function  **\n        outputs = model.distribute_strategy.run(run_step, args=(data,))\n    File \"/Users/gpalazzo/anaconda3/envs/msc/lib/python3.8/site-packages/keras/engine/training.py\", line 1249, in run_step  **\n        outputs = model.train_step(data)\n    File \"/Users/gpalazzo/anaconda3/envs/msc/lib/python3.8/site-packages/keras/engine/training.py\", line 1050, in train_step\n        y_pred = self(x, training=True)\n    File \"/Users/gpalazzo/anaconda3/envs/msc/lib/python3.8/site-packages/keras/utils/traceback_utils.py\", line 70, in error_handler\n        raise e.with_traceback(filtered_tb) from None\n    File \"/Users/gpalazzo/anaconda3/envs/msc/lib/python3.8/site-packages/keras/engine/input_spec.py\", line 298, in assert_input_compatibility\n        raise ValueError(\n\n    ValueError: Input 0 of layer \"sequential_27\" is incompatible with the layer: expected shape=(None, 1, 30), found shape=(16, 30)\n\n\n--------------------------------------------------------------------------------\n1 fits failed with the following error:\nTraceback (most recent call last):\n  File \"/Users/gpalazzo/anaconda3/envs/msc/lib/python3.8/site-packages/sklearn/model_selection/_validation.py\", line 686, in _fit_and_score\n    estimator.fit(X_train, y_train, **fit_params)\n  File \"/Users/gpalazzo/anaconda3/envs/msc/lib/python3.8/site-packages/keras/wrappers/scikit_learn.py\", line 248, in fit\n    return super().fit(x, y, **kwargs)\n  File \"/Users/gpalazzo/anaconda3/envs/msc/lib/python3.8/site-packages/keras/wrappers/scikit_learn.py\", line 175, in fit\n    history = self.model.fit(x, y, **fit_args)\n  File \"/Users/gpalazzo/anaconda3/envs/msc/lib/python3.8/site-packages/keras/utils/traceback_utils.py\", line 70, in error_handler\n    raise e.with_traceback(filtered_tb) from None\n  File \"/var/folders/dv/bgkf3r6s72j37pb4gm7dxtrr0000gn/T/__autograph_generated_filembb5nbmh.py\", line 15, in tf__train_function\n    retval_ = ag__.converted_call(ag__.ld(step_function), (ag__.ld(self), ag__.ld(iterator)), None, fscope)\nValueError: in user code:\n\n    File \"/Users/gpalazzo/anaconda3/envs/msc/lib/python3.8/site-packages/keras/engine/training.py\", line 1284, in train_function  *\n        return step_function(self, iterator)\n    File \"/Users/gpalazzo/anaconda3/envs/msc/lib/python3.8/site-packages/keras/engine/training.py\", line 1268, in step_function  **\n        outputs = model.distribute_strategy.run(run_step, args=(data,))\n    File \"/Users/gpalazzo/anaconda3/envs/msc/lib/python3.8/site-packages/keras/engine/training.py\", line 1249, in run_step  **\n        outputs = model.train_step(data)\n    File \"/Users/gpalazzo/anaconda3/envs/msc/lib/python3.8/site-packages/keras/engine/training.py\", line 1050, in train_step\n        y_pred = self(x, training=True)\n    File \"/Users/gpalazzo/anaconda3/envs/msc/lib/python3.8/site-packages/keras/utils/traceback_utils.py\", line 70, in error_handler\n        raise e.with_traceback(filtered_tb) from None\n    File \"/Users/gpalazzo/anaconda3/envs/msc/lib/python3.8/site-packages/keras/engine/input_spec.py\", line 298, in assert_input_compatibility\n        raise ValueError(\n\n    ValueError: Input 0 of layer \"sequential_28\" is incompatible with the layer: expected shape=(None, 1, 30), found shape=(16, 30)\n\n\n--------------------------------------------------------------------------------\n1 fits failed with the following error:\nTraceback (most recent call last):\n  File \"/Users/gpalazzo/anaconda3/envs/msc/lib/python3.8/site-packages/sklearn/model_selection/_validation.py\", line 686, in _fit_and_score\n    estimator.fit(X_train, y_train, **fit_params)\n  File \"/Users/gpalazzo/anaconda3/envs/msc/lib/python3.8/site-packages/keras/wrappers/scikit_learn.py\", line 248, in fit\n    return super().fit(x, y, **kwargs)\n  File \"/Users/gpalazzo/anaconda3/envs/msc/lib/python3.8/site-packages/keras/wrappers/scikit_learn.py\", line 175, in fit\n    history = self.model.fit(x, y, **fit_args)\n  File \"/Users/gpalazzo/anaconda3/envs/msc/lib/python3.8/site-packages/keras/utils/traceback_utils.py\", line 70, in error_handler\n    raise e.with_traceback(filtered_tb) from None\n  File \"/var/folders/dv/bgkf3r6s72j37pb4gm7dxtrr0000gn/T/__autograph_generated_filembb5nbmh.py\", line 15, in tf__train_function\n    retval_ = ag__.converted_call(ag__.ld(step_function), (ag__.ld(self), ag__.ld(iterator)), None, fscope)\nValueError: in user code:\n\n    File \"/Users/gpalazzo/anaconda3/envs/msc/lib/python3.8/site-packages/keras/engine/training.py\", line 1284, in train_function  *\n        return step_function(self, iterator)\n    File \"/Users/gpalazzo/anaconda3/envs/msc/lib/python3.8/site-packages/keras/engine/training.py\", line 1268, in step_function  **\n        outputs = model.distribute_strategy.run(run_step, args=(data,))\n    File \"/Users/gpalazzo/anaconda3/envs/msc/lib/python3.8/site-packages/keras/engine/training.py\", line 1249, in run_step  **\n        outputs = model.train_step(data)\n    File \"/Users/gpalazzo/anaconda3/envs/msc/lib/python3.8/site-packages/keras/engine/training.py\", line 1050, in train_step\n        y_pred = self(x, training=True)\n    File \"/Users/gpalazzo/anaconda3/envs/msc/lib/python3.8/site-packages/keras/utils/traceback_utils.py\", line 70, in error_handler\n        raise e.with_traceback(filtered_tb) from None\n    File \"/Users/gpalazzo/anaconda3/envs/msc/lib/python3.8/site-packages/keras/engine/input_spec.py\", line 298, in assert_input_compatibility\n        raise ValueError(\n\n    ValueError: Input 0 of layer \"sequential_29\" is incompatible with the layer: expected shape=(None, 1, 30), found shape=(16, 30)\n\n\n--------------------------------------------------------------------------------\n1 fits failed with the following error:\nTraceback (most recent call last):\n  File \"/Users/gpalazzo/anaconda3/envs/msc/lib/python3.8/site-packages/sklearn/model_selection/_validation.py\", line 686, in _fit_and_score\n    estimator.fit(X_train, y_train, **fit_params)\n  File \"/Users/gpalazzo/anaconda3/envs/msc/lib/python3.8/site-packages/keras/wrappers/scikit_learn.py\", line 248, in fit\n    return super().fit(x, y, **kwargs)\n  File \"/Users/gpalazzo/anaconda3/envs/msc/lib/python3.8/site-packages/keras/wrappers/scikit_learn.py\", line 175, in fit\n    history = self.model.fit(x, y, **fit_args)\n  File \"/Users/gpalazzo/anaconda3/envs/msc/lib/python3.8/site-packages/keras/utils/traceback_utils.py\", line 70, in error_handler\n    raise e.with_traceback(filtered_tb) from None\n  File \"/var/folders/dv/bgkf3r6s72j37pb4gm7dxtrr0000gn/T/__autograph_generated_filembb5nbmh.py\", line 15, in tf__train_function\n    retval_ = ag__.converted_call(ag__.ld(step_function), (ag__.ld(self), ag__.ld(iterator)), None, fscope)\nValueError: in user code:\n\n    File \"/Users/gpalazzo/anaconda3/envs/msc/lib/python3.8/site-packages/keras/engine/training.py\", line 1284, in train_function  *\n        return step_function(self, iterator)\n    File \"/Users/gpalazzo/anaconda3/envs/msc/lib/python3.8/site-packages/keras/engine/training.py\", line 1268, in step_function  **\n        outputs = model.distribute_strategy.run(run_step, args=(data,))\n    File \"/Users/gpalazzo/anaconda3/envs/msc/lib/python3.8/site-packages/keras/engine/training.py\", line 1249, in run_step  **\n        outputs = model.train_step(data)\n    File \"/Users/gpalazzo/anaconda3/envs/msc/lib/python3.8/site-packages/keras/engine/training.py\", line 1050, in train_step\n        y_pred = self(x, training=True)\n    File \"/Users/gpalazzo/anaconda3/envs/msc/lib/python3.8/site-packages/keras/utils/traceback_utils.py\", line 70, in error_handler\n        raise e.with_traceback(filtered_tb) from None\n    File \"/Users/gpalazzo/anaconda3/envs/msc/lib/python3.8/site-packages/keras/engine/input_spec.py\", line 298, in assert_input_compatibility\n        raise ValueError(\n\n    ValueError: Input 0 of layer \"sequential_30\" is incompatible with the layer: expected shape=(None, 1, 30), found shape=(16, 30)\n\n\n--------------------------------------------------------------------------------\n1 fits failed with the following error:\nTraceback (most recent call last):\n  File \"/Users/gpalazzo/anaconda3/envs/msc/lib/python3.8/site-packages/sklearn/model_selection/_validation.py\", line 686, in _fit_and_score\n    estimator.fit(X_train, y_train, **fit_params)\n  File \"/Users/gpalazzo/anaconda3/envs/msc/lib/python3.8/site-packages/keras/wrappers/scikit_learn.py\", line 248, in fit\n    return super().fit(x, y, **kwargs)\n  File \"/Users/gpalazzo/anaconda3/envs/msc/lib/python3.8/site-packages/keras/wrappers/scikit_learn.py\", line 175, in fit\n    history = self.model.fit(x, y, **fit_args)\n  File \"/Users/gpalazzo/anaconda3/envs/msc/lib/python3.8/site-packages/keras/utils/traceback_utils.py\", line 70, in error_handler\n    raise e.with_traceback(filtered_tb) from None\n  File \"/var/folders/dv/bgkf3r6s72j37pb4gm7dxtrr0000gn/T/__autograph_generated_filembb5nbmh.py\", line 15, in tf__train_function\n    retval_ = ag__.converted_call(ag__.ld(step_function), (ag__.ld(self), ag__.ld(iterator)), None, fscope)\nValueError: in user code:\n\n    File \"/Users/gpalazzo/anaconda3/envs/msc/lib/python3.8/site-packages/keras/engine/training.py\", line 1284, in train_function  *\n        return step_function(self, iterator)\n    File \"/Users/gpalazzo/anaconda3/envs/msc/lib/python3.8/site-packages/keras/engine/training.py\", line 1268, in step_function  **\n        outputs = model.distribute_strategy.run(run_step, args=(data,))\n    File \"/Users/gpalazzo/anaconda3/envs/msc/lib/python3.8/site-packages/keras/engine/training.py\", line 1249, in run_step  **\n        outputs = model.train_step(data)\n    File \"/Users/gpalazzo/anaconda3/envs/msc/lib/python3.8/site-packages/keras/engine/training.py\", line 1050, in train_step\n        y_pred = self(x, training=True)\n    File \"/Users/gpalazzo/anaconda3/envs/msc/lib/python3.8/site-packages/keras/utils/traceback_utils.py\", line 70, in error_handler\n        raise e.with_traceback(filtered_tb) from None\n    File \"/Users/gpalazzo/anaconda3/envs/msc/lib/python3.8/site-packages/keras/engine/input_spec.py\", line 298, in assert_input_compatibility\n        raise ValueError(\n\n    ValueError: Input 0 of layer \"sequential_31\" is incompatible with the layer: expected shape=(None, 1, 30), found shape=(16, 30)\n\n\n--------------------------------------------------------------------------------\n1 fits failed with the following error:\nTraceback (most recent call last):\n  File \"/Users/gpalazzo/anaconda3/envs/msc/lib/python3.8/site-packages/sklearn/model_selection/_validation.py\", line 686, in _fit_and_score\n    estimator.fit(X_train, y_train, **fit_params)\n  File \"/Users/gpalazzo/anaconda3/envs/msc/lib/python3.8/site-packages/keras/wrappers/scikit_learn.py\", line 248, in fit\n    return super().fit(x, y, **kwargs)\n  File \"/Users/gpalazzo/anaconda3/envs/msc/lib/python3.8/site-packages/keras/wrappers/scikit_learn.py\", line 175, in fit\n    history = self.model.fit(x, y, **fit_args)\n  File \"/Users/gpalazzo/anaconda3/envs/msc/lib/python3.8/site-packages/keras/utils/traceback_utils.py\", line 70, in error_handler\n    raise e.with_traceback(filtered_tb) from None\n  File \"/var/folders/dv/bgkf3r6s72j37pb4gm7dxtrr0000gn/T/__autograph_generated_filembb5nbmh.py\", line 15, in tf__train_function\n    retval_ = ag__.converted_call(ag__.ld(step_function), (ag__.ld(self), ag__.ld(iterator)), None, fscope)\nValueError: in user code:\n\n    File \"/Users/gpalazzo/anaconda3/envs/msc/lib/python3.8/site-packages/keras/engine/training.py\", line 1284, in train_function  *\n        return step_function(self, iterator)\n    File \"/Users/gpalazzo/anaconda3/envs/msc/lib/python3.8/site-packages/keras/engine/training.py\", line 1268, in step_function  **\n        outputs = model.distribute_strategy.run(run_step, args=(data,))\n    File \"/Users/gpalazzo/anaconda3/envs/msc/lib/python3.8/site-packages/keras/engine/training.py\", line 1249, in run_step  **\n        outputs = model.train_step(data)\n    File \"/Users/gpalazzo/anaconda3/envs/msc/lib/python3.8/site-packages/keras/engine/training.py\", line 1050, in train_step\n        y_pred = self(x, training=True)\n    File \"/Users/gpalazzo/anaconda3/envs/msc/lib/python3.8/site-packages/keras/utils/traceback_utils.py\", line 70, in error_handler\n        raise e.with_traceback(filtered_tb) from None\n    File \"/Users/gpalazzo/anaconda3/envs/msc/lib/python3.8/site-packages/keras/engine/input_spec.py\", line 298, in assert_input_compatibility\n        raise ValueError(\n\n    ValueError: Input 0 of layer \"sequential_32\" is incompatible with the layer: expected shape=(None, 1, 30), found shape=(16, 30)\n\n\n--------------------------------------------------------------------------------\n1 fits failed with the following error:\nTraceback (most recent call last):\n  File \"/Users/gpalazzo/anaconda3/envs/msc/lib/python3.8/site-packages/sklearn/model_selection/_validation.py\", line 686, in _fit_and_score\n    estimator.fit(X_train, y_train, **fit_params)\n  File \"/Users/gpalazzo/anaconda3/envs/msc/lib/python3.8/site-packages/keras/wrappers/scikit_learn.py\", line 248, in fit\n    return super().fit(x, y, **kwargs)\n  File \"/Users/gpalazzo/anaconda3/envs/msc/lib/python3.8/site-packages/keras/wrappers/scikit_learn.py\", line 175, in fit\n    history = self.model.fit(x, y, **fit_args)\n  File \"/Users/gpalazzo/anaconda3/envs/msc/lib/python3.8/site-packages/keras/utils/traceback_utils.py\", line 70, in error_handler\n    raise e.with_traceback(filtered_tb) from None\n  File \"/var/folders/dv/bgkf3r6s72j37pb4gm7dxtrr0000gn/T/__autograph_generated_filembb5nbmh.py\", line 15, in tf__train_function\n    retval_ = ag__.converted_call(ag__.ld(step_function), (ag__.ld(self), ag__.ld(iterator)), None, fscope)\nValueError: in user code:\n\n    File \"/Users/gpalazzo/anaconda3/envs/msc/lib/python3.8/site-packages/keras/engine/training.py\", line 1284, in train_function  *\n        return step_function(self, iterator)\n    File \"/Users/gpalazzo/anaconda3/envs/msc/lib/python3.8/site-packages/keras/engine/training.py\", line 1268, in step_function  **\n        outputs = model.distribute_strategy.run(run_step, args=(data,))\n    File \"/Users/gpalazzo/anaconda3/envs/msc/lib/python3.8/site-packages/keras/engine/training.py\", line 1249, in run_step  **\n        outputs = model.train_step(data)\n    File \"/Users/gpalazzo/anaconda3/envs/msc/lib/python3.8/site-packages/keras/engine/training.py\", line 1050, in train_step\n        y_pred = self(x, training=True)\n    File \"/Users/gpalazzo/anaconda3/envs/msc/lib/python3.8/site-packages/keras/utils/traceback_utils.py\", line 70, in error_handler\n        raise e.with_traceback(filtered_tb) from None\n    File \"/Users/gpalazzo/anaconda3/envs/msc/lib/python3.8/site-packages/keras/engine/input_spec.py\", line 298, in assert_input_compatibility\n        raise ValueError(\n\n    ValueError: Input 0 of layer \"sequential_33\" is incompatible with the layer: expected shape=(None, 1, 30), found shape=(16, 30)\n\n\n--------------------------------------------------------------------------------\n1 fits failed with the following error:\nTraceback (most recent call last):\n  File \"/Users/gpalazzo/anaconda3/envs/msc/lib/python3.8/site-packages/sklearn/model_selection/_validation.py\", line 686, in _fit_and_score\n    estimator.fit(X_train, y_train, **fit_params)\n  File \"/Users/gpalazzo/anaconda3/envs/msc/lib/python3.8/site-packages/keras/wrappers/scikit_learn.py\", line 248, in fit\n    return super().fit(x, y, **kwargs)\n  File \"/Users/gpalazzo/anaconda3/envs/msc/lib/python3.8/site-packages/keras/wrappers/scikit_learn.py\", line 175, in fit\n    history = self.model.fit(x, y, **fit_args)\n  File \"/Users/gpalazzo/anaconda3/envs/msc/lib/python3.8/site-packages/keras/utils/traceback_utils.py\", line 70, in error_handler\n    raise e.with_traceback(filtered_tb) from None\n  File \"/var/folders/dv/bgkf3r6s72j37pb4gm7dxtrr0000gn/T/__autograph_generated_filembb5nbmh.py\", line 15, in tf__train_function\n    retval_ = ag__.converted_call(ag__.ld(step_function), (ag__.ld(self), ag__.ld(iterator)), None, fscope)\nValueError: in user code:\n\n    File \"/Users/gpalazzo/anaconda3/envs/msc/lib/python3.8/site-packages/keras/engine/training.py\", line 1284, in train_function  *\n        return step_function(self, iterator)\n    File \"/Users/gpalazzo/anaconda3/envs/msc/lib/python3.8/site-packages/keras/engine/training.py\", line 1268, in step_function  **\n        outputs = model.distribute_strategy.run(run_step, args=(data,))\n    File \"/Users/gpalazzo/anaconda3/envs/msc/lib/python3.8/site-packages/keras/engine/training.py\", line 1249, in run_step  **\n        outputs = model.train_step(data)\n    File \"/Users/gpalazzo/anaconda3/envs/msc/lib/python3.8/site-packages/keras/engine/training.py\", line 1050, in train_step\n        y_pred = self(x, training=True)\n    File \"/Users/gpalazzo/anaconda3/envs/msc/lib/python3.8/site-packages/keras/utils/traceback_utils.py\", line 70, in error_handler\n        raise e.with_traceback(filtered_tb) from None\n    File \"/Users/gpalazzo/anaconda3/envs/msc/lib/python3.8/site-packages/keras/engine/input_spec.py\", line 298, in assert_input_compatibility\n        raise ValueError(\n\n    ValueError: Input 0 of layer \"sequential_34\" is incompatible with the layer: expected shape=(None, 1, 30), found shape=(16, 30)\n\n\n--------------------------------------------------------------------------------\n1 fits failed with the following error:\nTraceback (most recent call last):\n  File \"/Users/gpalazzo/anaconda3/envs/msc/lib/python3.8/site-packages/sklearn/model_selection/_validation.py\", line 686, in _fit_and_score\n    estimator.fit(X_train, y_train, **fit_params)\n  File \"/Users/gpalazzo/anaconda3/envs/msc/lib/python3.8/site-packages/keras/wrappers/scikit_learn.py\", line 248, in fit\n    return super().fit(x, y, **kwargs)\n  File \"/Users/gpalazzo/anaconda3/envs/msc/lib/python3.8/site-packages/keras/wrappers/scikit_learn.py\", line 175, in fit\n    history = self.model.fit(x, y, **fit_args)\n  File \"/Users/gpalazzo/anaconda3/envs/msc/lib/python3.8/site-packages/keras/utils/traceback_utils.py\", line 70, in error_handler\n    raise e.with_traceback(filtered_tb) from None\n  File \"/var/folders/dv/bgkf3r6s72j37pb4gm7dxtrr0000gn/T/__autograph_generated_filembb5nbmh.py\", line 15, in tf__train_function\n    retval_ = ag__.converted_call(ag__.ld(step_function), (ag__.ld(self), ag__.ld(iterator)), None, fscope)\nValueError: in user code:\n\n    File \"/Users/gpalazzo/anaconda3/envs/msc/lib/python3.8/site-packages/keras/engine/training.py\", line 1284, in train_function  *\n        return step_function(self, iterator)\n    File \"/Users/gpalazzo/anaconda3/envs/msc/lib/python3.8/site-packages/keras/engine/training.py\", line 1268, in step_function  **\n        outputs = model.distribute_strategy.run(run_step, args=(data,))\n    File \"/Users/gpalazzo/anaconda3/envs/msc/lib/python3.8/site-packages/keras/engine/training.py\", line 1249, in run_step  **\n        outputs = model.train_step(data)\n    File \"/Users/gpalazzo/anaconda3/envs/msc/lib/python3.8/site-packages/keras/engine/training.py\", line 1050, in train_step\n        y_pred = self(x, training=True)\n    File \"/Users/gpalazzo/anaconda3/envs/msc/lib/python3.8/site-packages/keras/utils/traceback_utils.py\", line 70, in error_handler\n        raise e.with_traceback(filtered_tb) from None\n    File \"/Users/gpalazzo/anaconda3/envs/msc/lib/python3.8/site-packages/keras/engine/input_spec.py\", line 298, in assert_input_compatibility\n        raise ValueError(\n\n    ValueError: Input 0 of layer \"sequential_35\" is incompatible with the layer: expected shape=(None, 1, 30), found shape=(16, 30)\n\n"
     ]
    }
   ],
   "source": [
    "def create_model_lstm(optimizer: str) -> Sequential:\n",
    "\n",
    "    # parameters\n",
    "    LAYERS = [20, 20, 20, 1] #[10, 10, 10, 1]                # number of units in hidden and output layers\n",
    "    N = X_train_scaled_seq.shape[2]                 # number of features\n",
    "    LR = 0.0005 #0.0005                            # learning rate of the gradient descent\n",
    "    LAMBD = 0.005 #0.001                         # lambda in L2 regularizaion\n",
    "    DP = 0.0 #0.0                             # dropout rate\n",
    "    RDP = 0.0 #0.0                            # recurrent dropout rate\n",
    "\n",
    "    # model\n",
    "    model = Sequential()\n",
    "    model.add(LSTM(\n",
    "        input_shape=(seq_length, N),\n",
    "        units=LAYERS[0],\n",
    "        activation='tanh',\n",
    "        recurrent_activation='hard_sigmoid',\n",
    "        kernel_regularizer=l2(LAMBD),\n",
    "        recurrent_regularizer=l2(LAMBD),\n",
    "        dropout=DP,\n",
    "        recurrent_dropout=RDP,\n",
    "        return_sequences=True,\n",
    "        return_state=False,\n",
    "        stateful=False,\n",
    "        unroll=False\n",
    "                ))\n",
    "    model.add(BatchNormalization())\n",
    "    model.add(LSTM(\n",
    "        units=LAYERS[1],\n",
    "        activation='tanh',\n",
    "        recurrent_activation='hard_sigmoid',\n",
    "        kernel_regularizer=l2(LAMBD),\n",
    "        recurrent_regularizer=l2(LAMBD),\n",
    "        dropout=DP,\n",
    "        recurrent_dropout=RDP,\n",
    "        return_sequences=True,\n",
    "        return_state=False,\n",
    "        stateful=False,\n",
    "        unroll=False\n",
    "                ))\n",
    "    model.add(BatchNormalization())\n",
    "    model.add(LSTM(\n",
    "        units=LAYERS[2],\n",
    "        activation='tanh',\n",
    "        recurrent_activation='hard_sigmoid',\n",
    "        kernel_regularizer=l2(LAMBD),\n",
    "        recurrent_regularizer=l2(LAMBD),\n",
    "        dropout=DP,\n",
    "        recurrent_dropout=RDP,\n",
    "        return_sequences=False,\n",
    "        return_state=False,\n",
    "        stateful=False,\n",
    "        unroll=False\n",
    "                ))\n",
    "    model.add(BatchNormalization())\n",
    "    model.add(Dense(\n",
    "        units=LAYERS[3],\n",
    "        activation='sigmoid'))\n",
    "    \n",
    "    model.compile(loss='binary_crossentropy', optimizer=optimizer, metrics=['accuracy'])\n",
    "    \n",
    "    return model\n",
    "\n",
    "\n",
    "lstm_model_params = {\n",
    "    'batch_size': [4, 16],\n",
    "    'optimizer': ['SGD', 'RMSprop', 'Adam']\n",
    "    }\n",
    "model = KerasClassifier(build_fn=create_model_lstm, epochs=10, verbose=1)\n",
    "\n",
    "grid = GridSearchCV(estimator=model, param_grid=lstm_model_params, n_jobs=1, cv=3)\n",
    "grid_result = grid.fit(X_train, y_train)\n",
    "\n",
    "print(\"Best accuracy of: %f using %s\" % (grid_result.best_score_, \n",
    "                                         grid_result.best_params_))"
   ]
  },
  {
   "cell_type": "code",
   "execution_count": null,
   "id": "af0680ee",
   "metadata": {},
   "outputs": [],
   "source": []
  }
 ],
 "metadata": {
  "kernelspec": {
   "display_name": "Kedro (crypto_thesis)",
   "language": "python",
   "name": "kedro_crypto_thesis"
  },
  "language_info": {
   "codemirror_mode": {
    "name": "ipython",
    "version": 3
   },
   "file_extension": ".py",
   "mimetype": "text/x-python",
   "name": "python",
   "nbconvert_exporter": "python",
   "pygments_lexer": "ipython3",
   "version": "3.8.16"
  }
 },
 "nbformat": 4,
 "nbformat_minor": 5
}
